Workbook

Sheet Вводные
D3: Год | J3: =F10 -> 2024 | K3: =J3+1 -> 2025 | L3: =K3+1 -> 2026 | M3: =L3+1 -> 2027 | N3: =M3+1 -> 2028 | O3: =N3+1 -> 2029 | P3: =O3+1 -> 2030 | Q3: =P3+1 -> 2031 | R3: =Q3+1 -> 2032 | ... BJ3: =BI3+1 -> 2076
D4: Возраст | J4: =J3 - $F$11 -> 31 | K4: =K3 - $F$11 -> 32 | L4: =L3 - $F$11 -> 33 | M4: =M3 - $F$11 -> 34 | N4: =N3 - $F$11 -> 35 | O4: =O3 - $F$11 -> 36 | P4: =P3 - $F$11 -> 37 | Q4: =Q3 - $F$11 -> 38 | ... BJ4: =BJ3 - $F$11 -> 83
D5: № периода | J5: =IF( J$3 = $F$10, 1, H$5 + 1 ) -> 1 | K5: =IF( K$3 = $F$10, 0, J$5 + 1 ) -> 2 | L5: =IF( L$3 = $F$10, 0, K$5 + 1 ) -> 3 | M5: =IF( M$3 = $F$10, 0, L$5 + 1 ) -> 4 | N5: =IF( N$3 = $F$10, 0, M$5 + 1 ) -> 5 | O5: =IF( O$3 = $F$10, 0, N$5 + 1 ) -> 6 | P5: =IF( P$3 = $F$10, 0, O$5 + 1 ) -> 7 | Q5: =IF( Q$3 = $F$10, 0, P$5 + 1 ) -> 8 | R5: =IF( R$3 = $F$10, 0, Q$5 + 1 ) -> 9 | ... BJ5: =IF( BJ$3 = $F$10, 0, BI$5 + 1 ) -> 53
B8: =MAX( $B$7:B7 ) + 1 -> 1 | D8: Технические
D10: Дата начала | E10: год | F10: 2024
D11: Год рождения | E11: год | F11: 1993
D12: Месяцев в году | E12: x | F12: 12
D14: Инфляция | E14: % | J14: 0.05 | K14: 0.03 | L14: 0.03 | M14: 0.03 | N14: 0.03 | O14: 0.03 | P14: 0.03 | Q14: 0.03 | R14: 0.03 | S14: 0.03 | T14: 0.03 | U14: 0.03 | V14: 0.03 | W14: 0.03 | X14: 0.03 | Y14: 0.03 | Z14: 0.03 | AA14: 0.03 | AB14: 0.03 | AC14: 0.03 | AD14: 0.03 | AE14: 0.03 | AF14: 0.03 | AG14: 0.03 | AH14: 0.03 | AI14: 0.03 | AJ14: 0.03 | AK14: 0.03 | AL14: 0.03 | AM14: 0.03 | AN14: 0.03 | AO14: 0.03 | AP14: 0.03 | AQ14: 0.03 | AR14: 0.03 | AS14: 0.03 | AT14: 0.03 | AU14: 0.03 | AV14: 0.03 | AW14: 0.03 | AX14: 0.03 | AY14: 0.03 | AZ14: 0.03 | BA14: 0.03 | BB14: 0.03 | BC14: 0.03 | BD14: 0.03 | BE14: 0.03 | BF14: 0.03 | BG14: 0.03 | BH14: 0.03 | BI14: 0.03 | BJ14: 0.03
D15: Доходность на инвестированный капитал | E15: % | F15: 0.06
B17: =MAX( $B$7:B16 ) + 1 -> 2 | D17: Доходы
C19: =MAX( $B$7:C18 ) + 0.1 -> 2.1 | D19: Ежемесячные доходы
D21: Ежемесячные доходы | F21: =SUM(F22:F26) -> 13000
D22: Income 1 | E22: USD / мес. | F22: 10000
D23: Income 2 | E23: USD / мес. | F23: 2000
D24: Income 3 | E24: USD / мес. | F24: 1000
D25: Ежемесячный доход 4 | E25: USD / мес. | F25: 0
D26: Ежемесячный доход 5 | E26: USD / мес. | F26: 0
D28: Период получения доходов
D29: =$D$22 -> Income 1 | E29: год | F29: 2024 | G29: 2076
D30: =$D$23 -> Income 2 | E30: год | F30: 2024 | G30: 2024
D31: =$D$24 -> Income 3 | E31: год | F31: 2024 | G31: 2076
D32: =$D$25 -> Ежемесячный доход 4 | E32: год | F32: 2025 | G32: 2076
D33: =$D$26 -> Ежемесячный доход 5 | E33: год | F33: 2024 | G33: 2076
D35: Темп роста ежемесячных доходов
D36: ="Темп роста " & D22 -> Темп роста Income 1 | E36: % | J36: 0 | K36: 0.5 | L36: =L$14 -> 0.03 | M36: =M$14 -> 0.03 | N36: =N$14 -> 0.03 | O36: =O$14 -> 0.03 | P36: =P$14 -> 0.03 | Q36: =Q$14 -> 0.03 | R36: =R$14 -> 0.03 | S36: =S$14 -> 0.03 | ... BJ36: =BJ$14 -> 0.03
D37: ="Темп роста " & D23 -> Темп роста Income 2 | E37: % | J37: 0 | K37: 0 | L37: 0 | M37: 0 | N37: 0 | O37: 0 | P37: 0 | Q37: 0 | R37: 0 | S37: 0 | T37: 0 | U37: 0 | V37: 0 | W37: 0 | X37: 0 | Y37: 0 | Z37: 0 | AA37: 0 | AB37: 0 | AC37: 0 | AD37: 0 | AE37: 0 | AF37: 0 | AG37: 0 | AH37: 0 | AI37: 0 | AJ37: 0 | AK37: 0 | AL37: 0 | AM37: 0 | AN37: 0 | AO37: 0 | AP37: 0 | AQ37: 0 | AR37: 0 | AS37: 0 | AT37: 0 | AU37: 0 | AV37: 0 | AW37: 0 | AX37: 0 | AY37: 0 | AZ37: 0 | BA37: 0 | BB37: 0 | BC37: 0 | BD37: 0 | BE37: 0 | BF37: 0 | BG37: 0 | BH37: 0 | BI37: 0 | BJ37: 0
D38: ="Темп роста " & D24 -> Темп роста Income 3 | E38: % | J38: 0 | K38: =K$14 -> 0.03 | L38: =L$14 -> 0.03 | M38: =M$14 -> 0.03 | N38: =N$14 -> 0.03 | O38: =O$14 -> 0.03 | P38: =P$14 -> 0.03 | Q38: =Q$14 -> 0.03 | R38: =R$14 -> 0.03 | ... BJ38: =BJ$14 -> 0.03
D39: ="Темп роста " & D25 -> Темп роста Ежемесячный доход 4 | E39: % | J39: 0 | K39: =K$14 -> 0.03 | L39: =L$14 -> 0.03 | M39: =M$14 -> 0.03 | N39: =N$14 -> 0.03 | O39: =O$14 -> 0.03 | P39: =P$14 -> 0.03 | Q39: =Q$14 -> 0.03 | R39: =R$14 -> 0.03 | ... BJ39: =BJ$14 -> 0.03
D40: ="Темп роста " & D26 -> Темп роста Ежемесячный доход 5 | E40: % | J40: 0 | K40: =K$14 -> 0.03 | L40: =L$14 -> 0.03 | M40: =M$14 -> 0.03 | N40: =N$14 -> 0.03 | O40: =O$14 -> 0.03 | P40: =P$14 -> 0.03 | Q40: =Q$14 -> 0.03 | R40: =R$14 -> 0.03 | ... BJ40: =BJ$14 -> 0.03
C42: =MAX( $B$7:C41 ) + 0.1 -> 2.2 | D42: Ежегодные доходы
D44: Ежегодные доходы | F44: =SUM(F45:F49) -> 0
D45: Ежегодный доход 1 | E45: USD / год | F45: 0
D46: Ежегодный доход 2 | E46: USD / год | F46: 0
D47: Ежегодный доход 3 | E47: USD / год | F47: 0
D48: Ежегодный доход 4 | E48: USD / год | F48: 0
D49: Ежегодный доход 5 | E49: USD / год | F49: 0
D51: Ежегодные доходы
D52: =Вводные!$D$45 -> Ежегодный доход 1 | E52: год | F52: 2024 | G52: 2076
D53: =Вводные!$D$46 -> Ежегодный доход 2 | E53: год | F53: 2024 | G53: 2076
D54: =Вводные!$D$47 -> Ежегодный доход 3 | E54: год | F54: 2024 | G54: 2076
...

Sheet Доходы
D3: =Вводные!D3 -> Год | J3: =Вводные!J3 -> 2024 | K3: =Вводные!K3 -> 2025 | L3: =Вводные!L3 -> 2026 | M3: =Вводные!M3 -> 2027 | N3: =Вводные!N3 -> 2028 | O3: =Вводные!O3 -> 2029 | P3: =Вводные!P3 -> 2030 | Q3: =Вводные!Q3 -> 2031 | ... BJ3: =Вводные!BJ3 -> 2076
D4: =Вводные!D4 -> Возраст | J4: =Вводные!J4 -> 31 | K4: =Вводные!K4 -> 32 | L4: =Вводные!L4 -> 33 | M4: =Вводные!M4 -> 34 | N4: =Вводные!N4 -> 35 | O4: =Вводные!O4 -> 36 | P4: =Вводные!P4 -> 37 | Q4: =Вводные!Q4 -> 38 | ... BJ4: =Вводные!BJ4 -> 83
D5: =Вводные!D5 -> № периода | J5: =Вводные!J5 -> 1 | K5: =Вводные!K5 -> 2 | L5: =Вводные!L5 -> 3 | M5: =Вводные!M5 -> 4 | N5: =Вводные!N5 -> 5 | O5: =Вводные!O5 -> 6 | P5: =Вводные!P5 -> 7 | Q5: =Вводные!Q5 -> 8 | ... BJ5: =Вводные!BJ5 -> 53
B8: =MAX( $B5:B$7 ) + 1 -> 1 | D8: Флаги
C10: =MAX( $B$7:C9 ) + 0.1 -> 1.1 | D10: Флаги получения дохода
D12: Ежемесячные доходы
D13: =Вводные!$D$22 -> Income 1 | E13: флаг | J13: =IF( AND(J$3 >= Вводные!$F29, J$3 <= Вводные!$G29), 1, 0) -> 1 | K13: =IF( AND(K$3 >= Вводные!$F29, K$3 <= Вводные!$G29), 1, 0) -> 1 | L13: =IF( AND(L$3 >= Вводные!$F29, L$3 <= Вводные!$G29), 1, 0) -> 1 | M13: =IF( AND(M$3 >= Вводные!$F29, M$3 <= Вводные!$G29), 1, 0) -> 1 | N13: =IF( AND(N$3 >= Вводные!$F29, N$3 <= Вводные!$G29), 1, 0) -> 1 | O13: =IF( AND(O$3 >= Вводные!$F29, O$3 <= Вводные!$G29), 1, 0) -> 1 | P13: =IF( AND(P$3 >= Вводные!$F29, P$3 <= Вводные!$G29), 1, 0) -> 1 | Q13: =IF( AND(Q$3 >= Вводные!$F29, Q$3 <= Вводные!$G29), 1, 0) -> 1 | ... BJ13: =IF( AND(BJ$3 >= Вводные!$F29, BJ$3 <= Вводные!$G29), 1, 0) -> 1
D14: =Вводные!$D$23 -> Income 2 | E14: флаг | J14: =IF( AND(J$3 >= Вводные!$F30, J$3 <= Вводные!$G30), 1, 0) -> 1 | K14: =IF( AND(K$3 >= Вводные!$F30, K$3 <= Вводные!$G30), 1, 0) -> 0 | L14: =IF( AND(L$3 >= Вводные!$F30, L$3 <= Вводные!$G30), 1, 0) -> 0 | M14: =IF( AND(M$3 >= Вводные!$F30, M$3 <= Вводные!$G30), 1, 0) -> 0 | N14: =IF( AND(N$3 >= Вводные!$F30, N$3 <= Вводные!$G30), 1, 0) -> 0 | O14: =IF( AND(O$3 >= Вводные!$F30, O$3 <= Вводные!$G30), 1, 0) -> 0 | P14: =IF( AND(P$3 >= Вводные!$F30, P$3 <= Вводные!$G30), 1, 0) -> 0 | Q14: =IF( AND(Q$3 >= Вводные!$F30, Q$3 <= Вводные!$G30), 1, 0) -> 0 | ... BJ14: =IF( AND(BJ$3 >= Вводные!$F30, BJ$3 <= Вводные!$G30), 1, 0) -> 0
D15: =Вводные!$D$24 -> Income 3 | E15: флаг | J15: =IF( AND(J$3 >= Вводные!$F31, J$3 <= Вводные!$G31), 1, 0) -> 1 | K15: =IF( AND(K$3 >= Вводные!$F31, K$3 <= Вводные!$G31), 1, 0) -> 1 | L15: =IF( AND(L$3 >= Вводные!$F31, L$3 <= Вводные!$G31), 1, 0) -> 1 | M15: =IF( AND(M$3 >= Вводные!$F31, M$3 <= Вводные!$G31), 1, 0) -> 1 | N15: =IF( AND(N$3 >= Вводные!$F31, N$3 <= Вводные!$G31), 1, 0) -> 1 | O15: =IF( AND(O$3 >= Вводные!$F31, O$3 <= Вводные!$G31), 1, 0) -> 1 | P15: =IF( AND(P$3 >= Вводные!$F31, P$3 <= Вводные!$G31), 1, 0) -> 1 | Q15: =IF( AND(Q$3 >= Вводные!$F31, Q$3 <= Вводные!$G31), 1, 0) -> 1 | ... BJ15: =IF( AND(BJ$3 >= Вводные!$F31, BJ$3 <= Вводные!$G31), 1, 0) -> 1
D16: =Вводные!$D$25 -> Ежемесячный доход 4 | E16: флаг | J16: =IF( AND(J$3 >= Вводные!$F32, J$3 <= Вводные!$G32), 1, 0) -> 0 | K16: =IF( AND(K$3 >= Вводные!$F32, K$3 <= Вводные!$G32), 1, 0) -> 1 | L16: =IF( AND(L$3 >= Вводные!$F32, L$3 <= Вводные!$G32), 1, 0) -> 1 | M16: =IF( AND(M$3 >= Вводные!$F32, M$3 <= Вводные!$G32), 1, 0) -> 1 | N16: =IF( AND(N$3 >= Вводные!$F32, N$3 <= Вводные!$G32), 1, 0) -> 1 | O16: =IF( AND(O$3 >= Вводные!$F32, O$3 <= Вводные!$G32), 1, 0) -> 1 | P16: =IF( AND(P$3 >= Вводные!$F32, P$3 <= Вводные!$G32), 1, 0) -> 1 | Q16: =IF( AND(Q$3 >= Вводные!$F32, Q$3 <= Вводные!$G32), 1, 0) -> 1 | ... BJ16: =IF( AND(BJ$3 >= Вводные!$F32, BJ$3 <= Вводные!$G32), 1, 0) -> 1
D17: =Вводные!$D$26 -> Ежемесячный доход 5 | E17: флаг | J17: =IF( AND(J$3 >= Вводные!$F33, J$3 <= Вводные!$G33), 1, 0) -> 1 | K17: =IF( AND(K$3 >= Вводные!$F33, K$3 <= Вводные!$G33), 1, 0) -> 1 | L17: =IF( AND(L$3 >= Вводные!$F33, L$3 <= Вводные!$G33), 1, 0) -> 1 | M17: =IF( AND(M$3 >= Вводные!$F33, M$3 <= Вводные!$G33), 1, 0) -> 1 | N17: =IF( AND(N$3 >= Вводные!$F33, N$3 <= Вводные!$G33), 1, 0) -> 1 | O17: =IF( AND(O$3 >= Вводные!$F33, O$3 <= Вводные!$G33), 1, 0) -> 1 | P17: =IF( AND(P$3 >= Вводные!$F33, P$3 <= Вводные!$G33), 1, 0) -> 1 | Q17: =IF( AND(Q$3 >= Вводные!$F33, Q$3 <= Вводные!$G33), 1, 0) -> 1 | ... BJ17: =IF( AND(BJ$3 >= Вводные!$F33, BJ$3 <= Вводные!$G33), 1, 0) -> 1
D19: Ежегодные доходы
D20: =Вводные!$D$45 -> Ежегодный доход 1 | E20: флаг | J20: =IF( AND(J$3 >= Вводные!$F52, J$3 <= Вводные!$G52), 1, 0) -> 1 | K20: =IF( AND(K$3 >= Вводные!$F52, K$3 <= Вводные!$G52), 1, 0) -> 1 | L20: =IF( AND(L$3 >= Вводные!$F52, L$3 <= Вводные!$G52), 1, 0) -> 1 | M20: =IF( AND(M$3 >= Вводные!$F52, M$3 <= Вводные!$G52), 1, 0) -> 1 | N20: =IF( AND(N$3 >= Вводные!$F52, N$3 <= Вводные!$G52), 1, 0) -> 1 | O20: =IF( AND(O$3 >= Вводные!$F52, O$3 <= Вводные!$G52), 1, 0) -> 1 | P20: =IF( AND(P$3 >= Вводные!$F52, P$3 <= Вводные!$G52), 1, 0) -> 1 | Q20: =IF( AND(Q$3 >= Вводные!$F52, Q$3 <= Вводные!$G52), 1, 0) -> 1 | ... BJ20: =IF( AND(BJ$3 >= Вводные!$F52, BJ$3 <= Вводные!$G52), 1, 0) -> 1
D21: =Вводные!$D$46 -> Ежегодный доход 2 | E21: флаг | J21: =IF( AND(J$3 >= Вводные!$F53, J$3 <= Вводные!$G53), 1, 0) -> 1 | K21: =IF( AND(K$3 >= Вводные!$F53, K$3 <= Вводные!$G53), 1, 0) -> 1 | L21: =IF( AND(L$3 >= Вводные!$F53, L$3 <= Вводные!$G53), 1, 0) -> 1 | M21: =IF( AND(M$3 >= Вводные!$F53, M$3 <= Вводные!$G53), 1, 0) -> 1 | N21: =IF( AND(N$3 >= Вводные!$F53, N$3 <= Вводные!$G53), 1, 0) -> 1 | O21: =IF( AND(O$3 >= Вводные!$F53, O$3 <= Вводные!$G53), 1, 0) -> 1 | P21: =IF( AND(P$3 >= Вводные!$F53, P$3 <= Вводные!$G53), 1, 0) -> 1 | Q21: =IF( AND(Q$3 >= Вводные!$F53, Q$3 <= Вводные!$G53), 1, 0) -> 1 | ... BJ21: =IF( AND(BJ$3 >= Вводные!$F53, BJ$3 <= Вводные!$G53), 1, 0) -> 1
D22: =Вводные!$D$47 -> Ежегодный доход 3 | E22: флаг | J22: =IF( AND(J$3 >= Вводные!$F54, J$3 <= Вводные!$G54), 1, 0) -> 1 | K22: =IF( AND(K$3 >= Вводные!$F54, K$3 <= Вводные!$G54), 1, 0) -> 1 | L22: =IF( AND(L$3 >= Вводные!$F54, L$3 <= Вводные!$G54), 1, 0) -> 1 | M22: =IF( AND(M$3 >= Вводные!$F54, M$3 <= Вводные!$G54), 1, 0) -> 1 | N22: =IF( AND(N$3 >= Вводные!$F54, N$3 <= Вводные!$G54), 1, 0) -> 1 | O22: =IF( AND(O$3 >= Вводные!$F54, O$3 <= Вводные!$G54), 1, 0) -> 1 | P22: =IF( AND(P$3 >= Вводные!$F54, P$3 <= Вводные!$G54), 1, 0) -> 1 | Q22: =IF( AND(Q$3 >= Вводные!$F54, Q$3 <= Вводные!$G54), 1, 0) -> 1 | ... BJ22: =IF( AND(BJ$3 >= Вводные!$F54, BJ$3 <= Вводные!$G54), 1, 0) -> 1
D23: =Вводные!$D$48 -> Ежегодный доход 4 | E23: флаг | J23: =IF( AND(J$3 >= Вводные!$F55, J$3 <= Вводные!$G55), 1, 0) -> 1 | K23: =IF( AND(K$3 >= Вводные!$F55, K$3 <= Вводные!$G55), 1, 0) -> 1 | L23: =IF( AND(L$3 >= Вводные!$F55, L$3 <= Вводные!$G55), 1, 0) -> 1 | M23: =IF( AND(M$3 >= Вводные!$F55, M$3 <= Вводные!$G55), 1, 0) -> 1 | N23: =IF( AND(N$3 >= Вводные!$F55, N$3 <= Вводные!$G55), 1, 0) -> 1 | O23: =IF( AND(O$3 >= Вводные!$F55, O$3 <= Вводные!$G55), 1, 0) -> 1 | P23: =IF( AND(P$3 >= Вводные!$F55, P$3 <= Вводные!$G55), 1, 0) -> 1 | Q23: =IF( AND(Q$3 >= Вводные!$F55, Q$3 <= Вводные!$G55), 1, 0) -> 1 | ... BJ23: =IF( AND(BJ$3 >= Вводные!$F55, BJ$3 <= Вводные!$G55), 1, 0) -> 1
D24: =Вводные!$D$49 -> Ежегодный доход 5 | E24: флаг | J24: =IF( AND(J$3 >= Вводные!$F56, J$3 <= Вводные!$G56), 1, 0) -> 1 | K24: =IF( AND(K$3 >= Вводные!$F56, K$3 <= Вводные!$G56), 1, 0) -> 1 | L24: =IF( AND(L$3 >= Вводные!$F56, L$3 <= Вводные!$G56), 1, 0) -> 1 | M24: =IF( AND(M$3 >= Вводные!$F56, M$3 <= Вводные!$G56), 1, 0) -> 1 | N24: =IF( AND(N$3 >= Вводные!$F56, N$3 <= Вводные!$G56), 1, 0) -> 1 | O24: =IF( AND(O$3 >= Вводные!$F56, O$3 <= Вводные!$G56), 1, 0) -> 1 | P24: =IF( AND(P$3 >= Вводные!$F56, P$3 <= Вводные!$G56), 1, 0) -> 1 | Q24: =IF( AND(Q$3 >= Вводные!$F56, Q$3 <= Вводные!$G56), 1, 0) -> 1 | ... BJ24: =IF( AND(BJ$3 >= Вводные!$F56, BJ$3 <= Вводные!$G56), 1, 0) -> 1
B26: =MAX( $B$7:B9 ) + 1 -> 2 | D26: Доходы
D28: Всего доходы | E28: USD / год | I28: =SUM(I32,I48) -> 156000 | J28: =SUM(J32,J48) -> 156000 | K28: =SUM(K32,K48) -> 192360 | L28: =SUM(L32,L48) -> 198130.8 | M28: =SUM(M32,M48) -> 204074.72 | N28: =SUM(N32,N48) -> 210196.97 | O28: =SUM(O32,O48) -> 216502.87 | P28: =SUM(P32,P48) -> 222997.96 | ... BJ28: =SUM(BJ32,BJ48) -> 868586.81
C30: =MAX( $B$7:C27 ) + 0.1 -> 2.1 | D30: Ежемесячные доходы
D32: Ежемесячные доходы | E32: USD / год | I32: =SUM(I33:I37) -> 156000 | J32: =SUM(J33:J37) -> 156000 | K32: =SUM(K33:K37) -> 192360 | L32: =SUM(L33:L37) -> 198130.8 | M32: =SUM(M33:M37) -> 204074.72 | N32: =SUM(N33:N37) -> 210196.97 | O32: =SUM(O33:O37) -> 216502.87 | P32: =SUM(P33:P37) -> 222997.96 | ... BJ32: =SUM(BJ33:BJ37) -> 868586.81
D33: =Вводные!$D$22 -> Income 1 | E33: USD / год | I33: =Вводные!F22 * Вводные!$F$12 -> 120000 | J33: =$I33 * J40 * J13 -> 120000 | K33: =$I33 * K40 * K13 -> 180000 | L33: =$I33 * L40 * L13 -> 185400 | M33: =$I33 * M40 * M13 -> 190962 | N33: =$I33 * N40 * N13 -> 196690.86 | O33: =$I33 * O40 * O13 -> 202591.59 | P33: =$I33 * P40 * P13 -> 208669.33 | Q33: =$I33 * Q40 * Q13 -> 214929.41 | ... BJ33: =$I33 * BJ40 * BJ13 -> 812776.18
D34: =Вводные!$D$23 -> Income 2 | E34: USD / год | I34: =Вводные!F23 * Вводные!$F$12 -> 24000 | J34: =$I34 * J41 * J14 -> 24000 | K34: =$I34 * K41 * K14 -> 0 | L34: =$I34 * L41 * L14 -> 0 | M34: =$I34 * M41 * M14 -> 0 | N34: =$I34 * N41 * N14 -> 0 | O34: =$I34 * O41 * O14 -> 0 | P34: =$I34 * P41 * P14 -> 0 | Q34: =$I34 * Q41 * Q14 -> 0 | ... BJ34: =$I34 * BJ41 * BJ14 -> 0
D35: =Вводные!$D$24 -> Income 3 | E35: USD / год | I35: =Вводные!F24 * Вводные!$F$12 -> 12000 | J35: =$I35 * J42 * J15 -> 12000 | K35: =$I35 * K42 * K15 -> 12360 | L35: =$I35 * L42 * L15 -> 12730.8 | M35: =$I35 * M42 * M15 -> 13112.724 | N35: =$I35 * N42 * N15 -> 13506.106 | O35: =$I35 * O42 * O15 -> 13911.289 | P35: =$I35 * P42 * P15 -> 14328.628 | Q35: =$I35 * Q42 * Q15 -> 14758.486 | ... BJ35: =$I35 * BJ42 * BJ15 -> 55810.631
D36: =Вводные!$D$25 -> Ежемесячный доход 4 | E36: USD / год | I36: =Вводные!F25 * Вводные!$F$12 -> 0 | J36: =$I36 * J43 * J16 -> 0 | K36: =$I36 * K43 * K16 -> 0 | L36: =$I36 * L43 * L16 -> 0 | M36: =$I36 * M43 * M16 -> 0 | N36: =$I36 * N43 * N16 -> 0 | O36: =$I36 * O43 * O16 -> 0 | P36: =$I36 * P43 * P16 -> 0 | Q36: =$I36 * Q43 * Q16 -> 0 | ... BJ36: =$I36 * BJ43 * BJ16 -> 0
D37: =Вводные!$D$26 -> Ежемесячный доход 5 | E37: USD / год | I37: =Вводные!F26 * Вводные!$F$12 -> 0 | J37: =$I37 * J44 * J17 -> 0 | K37: =$I37 * K44 * K17 -> 0 | L37: =$I37 * L44 * L17 -> 0 | M37: =$I37 * M44 * M17 -> 0 | N37: =$I37 * N44 * N17 -> 0 | O37: =$I37 * O44 * O17 -> 0 | P37: =$I37 * P44 * P17 -> 0 | Q37: =$I37 * Q44 * Q17 -> 0 | ... BJ37: =$I37 * BJ44 * BJ17 -> 0
D39: Темп роста ежемесячных доходов
D40: =Вводные!$D$36 -> Темп роста Income 1 | E40: % | I40: 1 | J40: =I40 * (1+Вводные!J36) -> 1 | K40: =J40 * (1+Вводные!K36) -> 1.5 | L40: =K40 * (1+Вводные!L36) -> 1.545 | M40: =L40 * (1+Вводные!M36) -> 1.59135 | N40: =M40 * (1+Вводные!N36) -> 1.6390905 | O40: =N40 * (1+Вводные!O36) -> 1.6882632 | P40: =O40 * (1+Вводные!P36) -> 1.7389111 | Q40: =P40 * (1+Вводные!Q36) -> 1.7910784 | ... BJ40: =BI40 * (1+Вводные!BJ36) -> 6.7731348
D41: =Вводные!$D$37 -> Темп роста Income 2 | E41: % | I41: 1 | J41: =I41 * (1+Вводные!J37) -> 1 | K41: =J41 * (1+Вводные!K37) -> 1 | L41: =K41 * (1+Вводные!L37) -> 1 | M41: =L41 * (1+Вводные!M37) -> 1 | N41: =M41 * (1+Вводные!N37) -> 1 | O41: =N41 * (1+Вводные!O37) -> 1 | P41: =O41 * (1+Вводные!P37) -> 1 | Q41: =P41 * (1+Вводные!Q37) -> 1 | ... BJ41: =BI41 * (1+Вводные!BJ37) -> 1
D42: =Вводные!$D$38 -> Темп роста Income 3 | E42: % | I42: 1 | J42: =I42 * (1+Вводные!J38) -> 1 | K42: =J42 * (1+Вводные!K38) -> 1.03 | L42: =K42 * (1+Вводные!L38) -> 1.0609 | M42: =L42 * (1+Вводные!M38) -> 1.092727 | N42: =M42 * (1+Вводные!N38) -> 1.1255088 | O42: =N42 * (1+Вводные!O38) -> 1.1592741 | P42: =O42 * (1+Вводные!P38) -> 1.1940523 | Q42: =P42 * (1+Вводные!Q38) -> 1.2298739 | ... BJ42: =BI42 * (1+Вводные!BJ38) -> 4.6508859
D43: =Вводные!$D$39 -> Темп роста Ежемесячный доход 4 | E43: % | I43: 1 | J43: =I43 * (1+Вводные!J39) -> 1 | K43: =J43 * (1+Вводные!K39) -> 1.03 | L43: =K43 * (1+Вводные!L39) -> 1.0609 | M43: =L43 * (1+Вводные!M39) -> 1.092727 | N43: =M43 * (1+Вводные!N39) -> 1.1255088 | O43: =N43 * (1+Вводные!O39) -> 1.1592741 | P43: =O43 * (1+Вводные!P39) -> 1.1940523 | Q43: =P43 * (1+Вводные!Q39) -> 1.2298739 | ... BJ43: =BI43 * (1+Вводные!BJ39) -> 4.6508859
D44: =Вводные!$D$40 -> Темп роста Ежемесячный доход 5 | E44: % | I44: 1 | J44: =I44 * (1+Вводные!J40) -> 1 | K44: =J44 * (1+Вводные!K40) -> 1.03 | L44: =K44 * (1+Вводные!L40) -> 1.0609 | M44: =L44 * (1+Вводные!M40) -> 1.092727 | N44: =M44 * (1+Вводные!N40) -> 1.1255088 | O44: =N44 * (1+Вводные!O40) -> 1.1592741 | P44: =O44 * (1+Вводные!P40) -> 1.1940523 | Q44: =P44 * (1+Вводные!Q40) -> 1.2298739 | ... BJ44: =BI44 * (1+Вводные!BJ40) -> 4.6508859
C46: =MAX( $B$7:C45 ) + 0.1 -> 2.2 | D46: Ежегодные доходы
D48: Ежегодные доходы | E48: USD / год | I48: =SUM(I49:I53) -> 0 | J48: =SUM(J49:J53) -> 0 | K48: =SUM(K49:K53) -> 0 | L48: =SUM(L49:L53) -> 0 | M48: =SUM(M49:M53) -> 0 | N48: =SUM(N49:N53) -> 0 | O48: =SUM(O49:O53) -> 0 | P48: =SUM(P49:P53) -> 0 | ... BJ48: =SUM(BJ49:BJ53) -> 0
D49: =Вводные!$D$45 -> Ежегодный доход 1 | E49: USD / год | I49: =Вводные!F45 -> 0 | J49: =$I49 * J56 * J20 -> 0 | K49: =$I49 * K56 * K20 -> 0 | L49: =$I49 * L56 * L20 -> 0 | M49: =$I49 * M56 * M20 -> 0 | N49: =$I49 * N56 * N20 -> 0 | O49: =$I49 * O56 * O20 -> 0 | P49: =$I49 * P56 * P20 -> 0 | Q49: =$I49 * Q56 * Q20 -> 0 | ... BJ49: =$I49 * BJ56 * BJ20 -> 0
D50: =Вводные!$D$46 -> Ежегодный доход 2 | E50: USD / год | I50: =Вводные!F46 -> 0 | J50: =$I50 * J57 * J21 -> 0 | K50: =$I50 * K57 * K21 -> 0 | L50: =$I50 * L57 * L21 -> 0 | M50: =$I50 * M57 * M21 -> 0 | N50: =$I50 * N57 * N21 -> 0 | O50: =$I50 * O57 * O21 -> 0 | P50: =$I50 * P57 * P21 -> 0 | Q50: =$I50 * Q57 * Q21 -> 0 | ... BJ50: =$I50 * BJ57 * BJ21 -> 0
D51: =Вводные!$D$47 -> Ежегодный доход 3 | E51: USD / год | I51: =Вводные!F47 -> 0 | J51: =$I51 * J58 * J22 -> 0 | K51: =$I51 * K58 * K22 -> 0 | L51: =$I51 * L58 * L22 -> 0 | M51: =$I51 * M58 * M22 -> 0 | N51: =$I51 * N58 * N22 -> 0 | O51: =$I51 * O58 * O22 -> 0 | P51: =$I51 * P58 * P22 -> 0 | Q51: =$I51 * Q58 * Q22 -> 0 | ... BJ51: =$I51 * BJ58 * BJ22 -> 0
D52: =Вводные!$D$48 -> Ежегодный доход 4 | E52: USD / год | I52: =Вводные!F48 -> 0 | J52: =$I52 * J59 * J23 -> 0 | K52: =$I52 * K59 * K23 -> 0 | L52: =$I52 * L59 * L23 -> 0 | M52: =$I52 * M59 * M23 -> 0 | N52: =$I52 * N59 * N23 -> 0 | O52: =$I52 * O59 * O23 -> 0 | P52: =$I52 * P59 * P23 -> 0 | Q52: =$I52 * Q59 * Q23 -> 0 | ... BJ52: =$I52 * BJ59 * BJ23 -> 0
D53: =Вводные!$D$49 -> Ежегодный доход 5 | E53: USD / год | I53: =Вводные!F49 -> 0 | J53: =$I53 * J60 * J24 -> 0 | K53: =$I53 * K60 * K24 -> 0 | L53: =$I53 * L60 * L24 -> 0 | M53: =$I53 * M60 * M24 -> 0 | N53: =$I53 * N60 * N24 -> 0 | O53: =$I53 * O60 * O24 -> 0 | P53: =$I53 * P60 * P24 -> 0 | Q53: =$I53 * Q60 * Q24 -> 0 | ... BJ53: =$I53 * BJ60 * BJ24 -> 0
D55: Темп роста ежегодных доходов
...

Sheet Расходы
D3: =Вводные!D3 -> Год | J3: =Вводные!J3 -> 2024 | K3: =Вводные!K3 -> 2025 | L3: =Вводные!L3 -> 2026 | M3: =Вводные!M3 -> 2027 | N3: =Вводные!N3 -> 2028 | O3: =Вводные!O3 -> 2029 | P3: =Вводные!P3 -> 2030 | Q3: =Вводные!Q3 -> 2031 | ... BJ3: =Вводные!BJ3 -> 2076
D4: =Вводные!D4 -> Возраст | J4: =Вводные!J4 -> 31 | K4: =Вводные!K4 -> 32 | L4: =Вводные!L4 -> 33 | M4: =Вводные!M4 -> 34 | N4: =Вводные!N4 -> 35 | O4: =Вводные!O4 -> 36 | P4: =Вводные!P4 -> 37 | Q4: =Вводные!Q4 -> 38 | ... BJ4: =Вводные!BJ4 -> 83
D5: =Вводные!D5 -> № периода | J5: =Вводные!J5 -> 1 | K5: =Вводные!K5 -> 2 | L5: =Вводные!L5 -> 3 | M5: =Вводные!M5 -> 4 | N5: =Вводные!N5 -> 5 | O5: =Вводные!O5 -> 6 | P5: =Вводные!P5 -> 7 | Q5: =Вводные!Q5 -> 8 | ... BJ5: =Вводные!BJ5 -> 53
B8: =MAX( $B5:B$7 ) + 1 -> 1 | D8: Флаги
C10: =MAX( $B$7:C9 ) + 0.1 -> 1.1 | D10: Флаги понесения расходов
D12: Ежемесячные расходы
D13: =Вводные!$D$70 -> Еда | E13: флаг | J13: =IF( AND(J$3 >= Вводные!$F142, J$3 <= Вводные!$G142), 1, 0) -> 1 | K13: =IF( AND(K$3 >= Вводные!$F142, K$3 <= Вводные!$G142), 1, 0) -> 1 | L13: =IF( AND(L$3 >= Вводные!$F142, L$3 <= Вводные!$G142), 1, 0) -> 1 | M13: =IF( AND(M$3 >= Вводные!$F142, M$3 <= Вводные!$G142), 1, 0) -> 1 | N13: =IF( AND(N$3 >= Вводные!$F142, N$3 <= Вводные!$G142), 1, 0) -> 1 | O13: =IF( AND(O$3 >= Вводные!$F142, O$3 <= Вводные!$G142), 1, 0) -> 1 | P13: =IF( AND(P$3 >= Вводные!$F142, P$3 <= Вводные!$G142), 1, 0) -> 1 | Q13: =IF( AND(Q$3 >= Вводные!$F142, Q$3 <= Вводные!$G142), 1, 0) -> 1 | ... BJ13: =IF( AND(BJ$3 >= Вводные!$F142, BJ$3 <= Вводные!$G142), 1, 0) -> 1
D14: =Вводные!$D$71 -> Садик | E14: флаг | J14: =IF( AND(J$3 >= Вводные!$F143, J$3 <= Вводные!$G143), 1, 0) -> 1 | K14: =IF( AND(K$3 >= Вводные!$F143, K$3 <= Вводные!$G143), 1, 0) -> 1 | L14: =IF( AND(L$3 >= Вводные!$F143, L$3 <= Вводные!$G143), 1, 0) -> 1 | M14: =IF( AND(M$3 >= Вводные!$F143, M$3 <= Вводные!$G143), 1, 0) -> 1 | N14: =IF( AND(N$3 >= Вводные!$F143, N$3 <= Вводные!$G143), 1, 0) -> 1 | O14: =IF( AND(O$3 >= Вводные!$F143, O$3 <= Вводные!$G143), 1, 0) -> 1 | P14: =IF( AND(P$3 >= Вводные!$F143, P$3 <= Вводные!$G143), 1, 0) -> 1 | Q14: =IF( AND(Q$3 >= Вводные!$F143, Q$3 <= Вводные!$G143), 1, 0) -> 1 | ... BJ14: =IF( AND(BJ$3 >= Вводные!$F143, BJ$3 <= Вводные!$G143), 1, 0) -> 1
D15: =Вводные!$D$72 -> Няня | E15: флаг | J15: =IF( AND(J$3 >= Вводные!$F144, J$3 <= Вводные!$G144), 1, 0) -> 1 | K15: =IF( AND(K$3 >= Вводные!$F144, K$3 <= Вводные!$G144), 1, 0) -> 1 | L15: =IF( AND(L$3 >= Вводные!$F144, L$3 <= Вводные!$G144), 1, 0) -> 1 | M15: =IF( AND(M$3 >= Вводные!$F144, M$3 <= Вводные!$G144), 1, 0) -> 1 | N15: =IF( AND(N$3 >= Вводные!$F144, N$3 <= Вводные!$G144), 1, 0) -> 1 | O15: =IF( AND(O$3 >= Вводные!$F144, O$3 <= Вводные!$G144), 1, 0) -> 1 | P15: =IF( AND(P$3 >= Вводные!$F144, P$3 <= Вводные!$G144), 1, 0) -> 1 | Q15: =IF( AND(Q$3 >= Вводные!$F144, Q$3 <= Вводные!$G144), 1, 0) -> 1 | ... BJ15: =IF( AND(BJ$3 >= Вводные!$F144, BJ$3 <= Вводные!$G144), 1, 0) -> 1
D16: =Вводные!$D$73 -> Ипотека | E16: флаг | J16: =IF( AND(J$3 >= Вводные!$F145, J$3 <= Вводные!$G145), 1, 0) -> 1 | K16: =IF( AND(K$3 >= Вводные!$F145, K$3 <= Вводные!$G145), 1, 0) -> 1 | L16: =IF( AND(L$3 >= Вводные!$F145, L$3 <= Вводные!$G145), 1, 0) -> 1 | M16: =IF( AND(M$3 >= Вводные!$F145, M$3 <= Вводные!$G145), 1, 0) -> 1 | N16: =IF( AND(N$3 >= Вводные!$F145, N$3 <= Вводные!$G145), 1, 0) -> 1 | O16: =IF( AND(O$3 >= Вводные!$F145, O$3 <= Вводные!$G145), 1, 0) -> 1 | P16: =IF( AND(P$3 >= Вводные!$F145, P$3 <= Вводные!$G145), 1, 0) -> 1 | Q16: =IF( AND(Q$3 >= Вводные!$F145, Q$3 <= Вводные!$G145), 1, 0) -> 1 | ... BJ16: =IF( AND(BJ$3 >= Вводные!$F145, BJ$3 <= Вводные!$G145), 1, 0) -> 0
D17: =Вводные!$D$74 -> Аренда квартиры + коммуналка | E17: флаг | J17: =IF( AND(J$3 >= Вводные!$F146, J$3 <= Вводные!$G146), 1, 0) -> 1 | K17: =IF( AND(K$3 >= Вводные!$F146, K$3 <= Вводные!$G146), 1, 0) -> 1 | L17: =IF( AND(L$3 >= Вводные!$F146, L$3 <= Вводные!$G146), 1, 0) -> 1 | M17: =IF( AND(M$3 >= Вводные!$F146, M$3 <= Вводные!$G146), 1, 0) -> 1 | N17: =IF( AND(N$3 >= Вводные!$F146, N$3 <= Вводные!$G146), 1, 0) -> 1 | O17: =IF( AND(O$3 >= Вводные!$F146, O$3 <= Вводные!$G146), 1, 0) -> 1 | P17: =IF( AND(P$3 >= Вводные!$F146, P$3 <= Вводные!$G146), 1, 0) -> 1 | Q17: =IF( AND(Q$3 >= Вводные!$F146, Q$3 <= Вводные!$G146), 1, 0) -> 1 | ... BJ17: =IF( AND(BJ$3 >= Вводные!$F146, BJ$3 <= Вводные!$G146), 1, 0) -> 1
D18: =Вводные!$D$75 -> Связь + интернет | E18: флаг | J18: =IF( AND(J$3 >= Вводные!$F147, J$3 <= Вводные!$G147), 1, 0) -> 1 | K18: =IF( AND(K$3 >= Вводные!$F147, K$3 <= Вводные!$G147), 1, 0) -> 1 | L18: =IF( AND(L$3 >= Вводные!$F147, L$3 <= Вводные!$G147), 1, 0) -> 1 | M18: =IF( AND(M$3 >= Вводные!$F147, M$3 <= Вводные!$G147), 1, 0) -> 1 | N18: =IF( AND(N$3 >= Вводные!$F147, N$3 <= Вводные!$G147), 1, 0) -> 1 | O18: =IF( AND(O$3 >= Вводные!$F147, O$3 <= Вводные!$G147), 1, 0) -> 1 | P18: =IF( AND(P$3 >= Вводные!$F147, P$3 <= Вводные!$G147), 1, 0) -> 1 | Q18: =IF( AND(Q$3 >= Вводные!$F147, Q$3 <= Вводные!$G147), 1, 0) -> 1 | ... BJ18: =IF( AND(BJ$3 >= Вводные!$F147, BJ$3 <= Вводные!$G147), 1, 0) -> 1
D19: =Вводные!$D$76 -> Командировки | E19: флаг | J19: =IF( AND(J$3 >= Вводные!$F148, J$3 <= Вводные!$G148), 1, 0) -> 1 | K19: =IF( AND(K$3 >= Вводные!$F148, K$3 <= Вводные!$G148), 1, 0) -> 1 | L19: =IF( AND(L$3 >= Вводные!$F148, L$3 <= Вводные!$G148), 1, 0) -> 1 | M19: =IF( AND(M$3 >= Вводные!$F148, M$3 <= Вводные!$G148), 1, 0) -> 1 | N19: =IF( AND(N$3 >= Вводные!$F148, N$3 <= Вводные!$G148), 1, 0) -> 1 | O19: =IF( AND(O$3 >= Вводные!$F148, O$3 <= Вводные!$G148), 1, 0) -> 1 | P19: =IF( AND(P$3 >= Вводные!$F148, P$3 <= Вводные!$G148), 1, 0) -> 1 | Q19: =IF( AND(Q$3 >= Вводные!$F148, Q$3 <= Вводные!$G148), 1, 0) -> 1 | ... BJ19: =IF( AND(BJ$3 >= Вводные!$F148, BJ$3 <= Вводные!$G148), 1, 0) -> 1
D20: =Вводные!$D$77 -> Прочее | E20: флаг | J20: =IF( AND(J$3 >= Вводные!$F149, J$3 <= Вводные!$G149), 1, 0) -> 1 | K20: =IF( AND(K$3 >= Вводные!$F149, K$3 <= Вводные!$G149), 1, 0) -> 1 | L20: =IF( AND(L$3 >= Вводные!$F149, L$3 <= Вводные!$G149), 1, 0) -> 1 | M20: =IF( AND(M$3 >= Вводные!$F149, M$3 <= Вводные!$G149), 1, 0) -> 1 | N20: =IF( AND(N$3 >= Вводные!$F149, N$3 <= Вводные!$G149), 1, 0) -> 1 | O20: =IF( AND(O$3 >= Вводные!$F149, O$3 <= Вводные!$G149), 1, 0) -> 1 | P20: =IF( AND(P$3 >= Вводные!$F149, P$3 <= Вводные!$G149), 1, 0) -> 1 | Q20: =IF( AND(Q$3 >= Вводные!$F149, Q$3 <= Вводные!$G149), 1, 0) -> 1 | ... BJ20: =IF( AND(BJ$3 >= Вводные!$F149, BJ$3 <= Вводные!$G149), 1, 0) -> 1
D21: =Вводные!$D$78 -> Ежемесячный расход 9 | E21: флаг | J21: =IF( AND(J$3 >= Вводные!$F150, J$3 <= Вводные!$G150), 1, 0) -> 1 | K21: =IF( AND(K$3 >= Вводные!$F150, K$3 <= Вводные!$G150), 1, 0) -> 1 | L21: =IF( AND(L$3 >= Вводные!$F150, L$3 <= Вводные!$G150), 1, 0) -> 1 | M21: =IF( AND(M$3 >= Вводные!$F150, M$3 <= Вводные!$G150), 1, 0) -> 1 | N21: =IF( AND(N$3 >= Вводные!$F150, N$3 <= Вводные!$G150), 1, 0) -> 1 | O21: =IF( AND(O$3 >= Вводные!$F150, O$3 <= Вводные!$G150), 1, 0) -> 1 | P21: =IF( AND(P$3 >= Вводные!$F150, P$3 <= Вводные!$G150), 1, 0) -> 1 | Q21: =IF( AND(Q$3 >= Вводные!$F150, Q$3 <= Вводные!$G150), 1, 0) -> 1 | ... BJ21: =IF( AND(BJ$3 >= Вводные!$F150, BJ$3 <= Вводные!$G150), 1, 0) -> 1
D22: =Вводные!$D$79 -> Ежемесячный расход 10 | E22: флаг | J22: =IF( AND(J$3 >= Вводные!$F151, J$3 <= Вводные!$G151), 1, 0) -> 1 | K22: =IF( AND(K$3 >= Вводные!$F151, K$3 <= Вводные!$G151), 1, 0) -> 1 | L22: =IF( AND(L$3 >= Вводные!$F151, L$3 <= Вводные!$G151), 1, 0) -> 1 | M22: =IF( AND(M$3 >= Вводные!$F151, M$3 <= Вводные!$G151), 1, 0) -> 1 | N22: =IF( AND(N$3 >= Вводные!$F151, N$3 <= Вводные!$G151), 1, 0) -> 1 | O22: =IF( AND(O$3 >= Вводные!$F151, O$3 <= Вводные!$G151), 1, 0) -> 1 | P22: =IF( AND(P$3 >= Вводные!$F151, P$3 <= Вводные!$G151), 1, 0) -> 1 | Q22: =IF( AND(Q$3 >= Вводные!$F151, Q$3 <= Вводные!$G151), 1, 0) -> 1 | ... BJ22: =IF( AND(BJ$3 >= Вводные!$F151, BJ$3 <= Вводные!$G151), 1, 0) -> 1
D23: =Вводные!$D$80 -> Ежемесячный расход 11 | E23: флаг | J23: =IF( AND(J$3 >= Вводные!$F152, J$3 <= Вводные!$G152), 1, 0) -> 1 | K23: =IF( AND(K$3 >= Вводные!$F152, K$3 <= Вводные!$G152), 1, 0) -> 1 | L23: =IF( AND(L$3 >= Вводные!$F152, L$3 <= Вводные!$G152), 1, 0) -> 1 | M23: =IF( AND(M$3 >= Вводные!$F152, M$3 <= Вводные!$G152), 1, 0) -> 1 | N23: =IF( AND(N$3 >= Вводные!$F152, N$3 <= Вводные!$G152), 1, 0) -> 1 | O23: =IF( AND(O$3 >= Вводные!$F152, O$3 <= Вводные!$G152), 1, 0) -> 1 | P23: =IF( AND(P$3 >= Вводные!$F152, P$3 <= Вводные!$G152), 1, 0) -> 1 | Q23: =IF( AND(Q$3 >= Вводные!$F152, Q$3 <= Вводные!$G152), 1, 0) -> 1 | ... BJ23: =IF( AND(BJ$3 >= Вводные!$F152, BJ$3 <= Вводные!$G152), 1, 0) -> 1
D24: =Вводные!$D$81 -> Ежемесячный расход 12 | E24: флаг | J24: =IF( AND(J$3 >= Вводные!$F153, J$3 <= Вводные!$G153), 1, 0) -> 1 | K24: =IF( AND(K$3 >= Вводные!$F153, K$3 <= Вводные!$G153), 1, 0) -> 1 | L24: =IF( AND(L$3 >= Вводные!$F153, L$3 <= Вводные!$G153), 1, 0) -> 1 | M24: =IF( AND(M$3 >= Вводные!$F153, M$3 <= Вводные!$G153), 1, 0) -> 1 | N24: =IF( AND(N$3 >= Вводные!$F153, N$3 <= Вводные!$G153), 1, 0) -> 1 | O24: =IF( AND(O$3 >= Вводные!$F153, O$3 <= Вводные!$G153), 1, 0) -> 1 | P24: =IF( AND(P$3 >= Вводные!$F153, P$3 <= Вводные!$G153), 1, 0) -> 1 | Q24: =IF( AND(Q$3 >= Вводные!$F153, Q$3 <= Вводные!$G153), 1, 0) -> 1 | ... BJ24: =IF( AND(BJ$3 >= Вводные!$F153, BJ$3 <= Вводные!$G153), 1, 0) -> 1
D25: =Вводные!$D$82 -> Ежемесячный расход 13 | E25: флаг | J25: =IF( AND(J$3 >= Вводные!$F154, J$3 <= Вводные!$G154), 1, 0) -> 1 | K25: =IF( AND(K$3 >= Вводные!$F154, K$3 <= Вводные!$G154), 1, 0) -> 1 | L25: =IF( AND(L$3 >= Вводные!$F154, L$3 <= Вводные!$G154), 1, 0) -> 1 | M25: =IF( AND(M$3 >= Вводные!$F154, M$3 <= Вводные!$G154), 1, 0) -> 1 | N25: =IF( AND(N$3 >= Вводные!$F154, N$3 <= Вводные!$G154), 1, 0) -> 1 | O25: =IF( AND(O$3 >= Вводные!$F154, O$3 <= Вводные!$G154), 1, 0) -> 1 | P25: =IF( AND(P$3 >= Вводные!$F154, P$3 <= Вводные!$G154), 1, 0) -> 1 | Q25: =IF( AND(Q$3 >= Вводные!$F154, Q$3 <= Вводные!$G154), 1, 0) -> 1 | ... BJ25: =IF( AND(BJ$3 >= Вводные!$F154, BJ$3 <= Вводные!$G154), 1, 0) -> 1
D26: =Вводные!$D$83 -> Ежемесячный расход 14 | E26: флаг | J26: =IF( AND(J$3 >= Вводные!$F155, J$3 <= Вводные!$G155), 1, 0) -> 1 | K26: =IF( AND(K$3 >= Вводные!$F155, K$3 <= Вводные!$G155), 1, 0) -> 1 | L26: =IF( AND(L$3 >= Вводные!$F155, L$3 <= Вводные!$G155), 1, 0) -> 1 | M26: =IF( AND(M$3 >= Вводные!$F155, M$3 <= Вводные!$G155), 1, 0) -> 1 | N26: =IF( AND(N$3 >= Вводные!$F155, N$3 <= Вводные!$G155), 1, 0) -> 1 | O26: =IF( AND(O$3 >= Вводные!$F155, O$3 <= Вводные!$G155), 1, 0) -> 1 | P26: =IF( AND(P$3 >= Вводные!$F155, P$3 <= Вводные!$G155), 1, 0) -> 1 | Q26: =IF( AND(Q$3 >= Вводные!$F155, Q$3 <= Вводные!$G155), 1, 0) -> 1 | ... BJ26: =IF( AND(BJ$3 >= Вводные!$F155, BJ$3 <= Вводные!$G155), 1, 0) -> 1
D27: =Вводные!$D$84 -> Ежемесячный расход 15 | E27: флаг | J27: =IF( AND(J$3 >= Вводные!$F156, J$3 <= Вводные!$G156), 1, 0) -> 1 | K27: =IF( AND(K$3 >= Вводные!$F156, K$3 <= Вводные!$G156), 1, 0) -> 1 | L27: =IF( AND(L$3 >= Вводные!$F156, L$3 <= Вводные!$G156), 1, 0) -> 1 | M27: =IF( AND(M$3 >= Вводные!$F156, M$3 <= Вводные!$G156), 1, 0) -> 1 | N27: =IF( AND(N$3 >= Вводные!$F156, N$3 <= Вводные!$G156), 1, 0) -> 1 | O27: =IF( AND(O$3 >= Вводные!$F156, O$3 <= Вводные!$G156), 1, 0) -> 1 | P27: =IF( AND(P$3 >= Вводные!$F156, P$3 <= Вводные!$G156), 1, 0) -> 1 | Q27: =IF( AND(Q$3 >= Вводные!$F156, Q$3 <= Вводные!$G156), 1, 0) -> 1 | ... BJ27: =IF( AND(BJ$3 >= Вводные!$F156, BJ$3 <= Вводные!$G156), 1, 0) -> 1
D28: =Вводные!$D$85 -> Ежемесячный расход 16 | E28: флаг | J28: =IF( AND(J$3 >= Вводные!$F157, J$3 <= Вводные!$G157), 1, 0) -> 1 | K28: =IF( AND(K$3 >= Вводные!$F157, K$3 <= Вводные!$G157), 1, 0) -> 1 | L28: =IF( AND(L$3 >= Вводные!$F157, L$3 <= Вводные!$G157), 1, 0) -> 1 | M28: =IF( AND(M$3 >= Вводные!$F157, M$3 <= Вводные!$G157), 1, 0) -> 1 | N28: =IF( AND(N$3 >= Вводные!$F157, N$3 <= Вводные!$G157), 1, 0) -> 1 | O28: =IF( AND(O$3 >= Вводные!$F157, O$3 <= Вводные!$G157), 1, 0) -> 1 | P28: =IF( AND(P$3 >= Вводные!$F157, P$3 <= Вводные!$G157), 1, 0) -> 1 | Q28: =IF( AND(Q$3 >= Вводные!$F157, Q$3 <= Вводные!$G157), 1, 0) -> 1 | ... BJ28: =IF( AND(BJ$3 >= Вводные!$F157, BJ$3 <= Вводные!$G157), 1, 0) -> 1
D29: =Вводные!$D$86 -> Ежемесячный расход 17 | E29: флаг | J29: =IF( AND(J$3 >= Вводные!$F158, J$3 <= Вводные!$G158), 1, 0) -> 1 | K29: =IF( AND(K$3 >= Вводные!$F158, K$3 <= Вводные!$G158), 1, 0) -> 1 | L29: =IF( AND(L$3 >= Вводные!$F158, L$3 <= Вводные!$G158), 1, 0) -> 1 | M29: =IF( AND(M$3 >= Вводные!$F158, M$3 <= Вводные!$G158), 1, 0) -> 1 | N29: =IF( AND(N$3 >= Вводные!$F158, N$3 <= Вводные!$G158), 1, 0) -> 1 | O29: =IF( AND(O$3 >= Вводные!$F158, O$3 <= Вводные!$G158), 1, 0) -> 1 | P29: =IF( AND(P$3 >= Вводные!$F158, P$3 <= Вводные!$G158), 1, 0) -> 1 | Q29: =IF( AND(Q$3 >= Вводные!$F158, Q$3 <= Вводные!$G158), 1, 0) -> 1 | ... BJ29: =IF( AND(BJ$3 >= Вводные!$F158, BJ$3 <= Вводные!$G158), 1, 0) -> 1
D30: =Вводные!$D$87 -> Ежемесячный расход 18 | E30: флаг | J30: =IF( AND(J$3 >= Вводные!$F159, J$3 <= Вводные!$G159), 1, 0) -> 1 | K30: =IF( AND(K$3 >= Вводные!$F159, K$3 <= Вводные!$G159), 1, 0) -> 1 | L30: =IF( AND(L$3 >= Вводные!$F159, L$3 <= Вводные!$G159), 1, 0) -> 1 | M30: =IF( AND(M$3 >= Вводные!$F159, M$3 <= Вводные!$G159), 1, 0) -> 1 | N30: =IF( AND(N$3 >= Вводные!$F159, N$3 <= Вводные!$G159), 1, 0) -> 1 | O30: =IF( AND(O$3 >= Вводные!$F159, O$3 <= Вводные!$G159), 1, 0) -> 1 | P30: =IF( AND(P$3 >= Вводные!$F159, P$3 <= Вводные!$G159), 1, 0) -> 1 | Q30: =IF( AND(Q$3 >= Вводные!$F159, Q$3 <= Вводные!$G159), 1, 0) -> 1 | ... BJ30: =IF( AND(BJ$3 >= Вводные!$F159, BJ$3 <= Вводные!$G159), 1, 0) -> 1
D31: =Вводные!$D$88 -> Ежемесячный расход 19 | E31: флаг | J31: =IF( AND(J$3 >= Вводные!$F160, J$3 <= Вводные!$G160), 1, 0) -> 1 | K31: =IF( AND(K$3 >= Вводные!$F160, K$3 <= Вводные!$G160), 1, 0) -> 1 | L31: =IF( AND(L$3 >= Вводные!$F160, L$3 <= Вводные!$G160), 1, 0) -> 1 | M31: =IF( AND(M$3 >= Вводные!$F160, M$3 <= Вводные!$G160), 1, 0) -> 1 | N31: =IF( AND(N$3 >= Вводные!$F160, N$3 <= Вводные!$G160), 1, 0) -> 1 | O31: =IF( AND(O$3 >= Вводные!$F160, O$3 <= Вводные!$G160), 1, 0) -> 1 | P31: =IF( AND(P$3 >= Вводные!$F160, P$3 <= Вводные!$G160), 1, 0) -> 1 | Q31: =IF( AND(Q$3 >= Вводные!$F160, Q$3 <= Вводные!$G160), 1, 0) -> 1 | ... BJ31: =IF( AND(BJ$3 >= Вводные!$F160, BJ$3 <= Вводные!$G160), 1, 0) -> 1
D32: =Вводные!$D$89 -> Ежемесячный расход 20 | E32: флаг | J32: =IF( AND(J$3 >= Вводные!$F161, J$3 <= Вводные!$G161), 1, 0) -> 1 | K32: =IF( AND(K$3 >= Вводные!$F161, K$3 <= Вводные!$G161), 1, 0) -> 1 | L32: =IF( AND(L$3 >= Вводные!$F161, L$3 <= Вводные!$G161), 1, 0) -> 1 | M32: =IF( AND(M$3 >= Вводные!$F161, M$3 <= Вводные!$G161), 1, 0) -> 1 | N32: =IF( AND(N$3 >= Вводные!$F161, N$3 <= Вводные!$G161), 1, 0) -> 1 | O32: =IF( AND(O$3 >= Вводные!$F161, O$3 <= Вводные!$G161), 1, 0) -> 1 | P32: =IF( AND(P$3 >= Вводные!$F161, P$3 <= Вводные!$G161), 1, 0) -> 1 | Q32: =IF( AND(Q$3 >= Вводные!$F161, Q$3 <= Вводные!$G161), 1, 0) -> 1 | ... BJ32: =IF( AND(BJ$3 >= Вводные!$F161, BJ$3 <= Вводные!$G161), 1, 0) -> 1
D34: Ежегодные расходы
D35: =Вводные!$D$116 -> Страховка | E35: флаг | J35: =IF( AND(J$3 >= Вводные!$F164, J$3 <= Вводные!$G164), 1, 0) -> 1 | K35: =IF( AND(K$3 >= Вводные!$F164, K$3 <= Вводные!$G164), 1, 0) -> 1 | L35: =IF( AND(L$3 >= Вводные!$F164, L$3 <= Вводные!$G164), 1, 0) -> 1 | M35: =IF( AND(M$3 >= Вводные!$F164, M$3 <= Вводные!$G164), 1, 0) -> 1 | N35: =IF( AND(N$3 >= Вводные!$F164, N$3 <= Вводные!$G164), 1, 0) -> 1 | O35: =IF( AND(O$3 >= Вводные!$F164, O$3 <= Вводные!$G164), 1, 0) -> 1 | P35: =IF( AND(P$3 >= Вводные!$F164, P$3 <= Вводные!$G164), 1, 0) -> 1 | Q35: =IF( AND(Q$3 >= Вводные!$F164, Q$3 <= Вводные!$G164), 1, 0) -> 1 | ... BJ35: =IF( AND(BJ$3 >= Вводные!$F164, BJ$3 <= Вводные!$G164), 1, 0) -> 1
D36: =Вводные!$D$117 -> Детский сад / школа | E36: флаг | J36: =IF( AND(J$3 >= Вводные!$F165, J$3 <= Вводные!$G165), 1, 0) -> 1 | K36: =IF( AND(K$3 >= Вводные!$F165, K$3 <= Вводные!$G165), 1, 0) -> 1 | L36: =IF( AND(L$3 >= Вводные!$F165, L$3 <= Вводные!$G165), 1, 0) -> 1 | M36: =IF( AND(M$3 >= Вводные!$F165, M$3 <= Вводные!$G165), 1, 0) -> 1 | N36: =IF( AND(N$3 >= Вводные!$F165, N$3 <= Вводные!$G165), 1, 0) -> 1 | O36: =IF( AND(O$3 >= Вводные!$F165, O$3 <= Вводные!$G165), 1, 0) -> 1 | P36: =IF( AND(P$3 >= Вводные!$F165, P$3 <= Вводные!$G165), 1, 0) -> 1 | Q36: =IF( AND(Q$3 >= Вводные!$F165, Q$3 <= Вводные!$G165), 1, 0) -> 1 | ... BJ36: =IF( AND(BJ$3 >= Вводные!$F165, BJ$3 <= Вводные!$G165), 1, 0) -> 0
D37: =Вводные!$D$118 -> Страховка по ипотеке | E37: флаг | J37: =IF( AND(J$3 >= Вводные!$F166, J$3 <= Вводные!$G166), 1, 0) -> 1 | K37: =IF( AND(K$3 >= Вводные!$F166, K$3 <= Вводные!$G166), 1, 0) -> 1 | L37: =IF( AND(L$3 >= Вводные!$F166, L$3 <= Вводные!$G166), 1, 0) -> 1 | M37: =IF( AND(M$3 >= Вводные!$F166, M$3 <= Вводные!$G166), 1, 0) -> 1 | N37: =IF( AND(N$3 >= Вводные!$F166, N$3 <= Вводные!$G166), 1, 0) -> 1 | O37: =IF( AND(O$3 >= Вводные!$F166, O$3 <= Вводные!$G166), 1, 0) -> 1 | P37: =IF( AND(P$3 >= Вводные!$F166, P$3 <= Вводные!$G166), 1, 0) -> 1 | Q37: =IF( AND(Q$3 >= Вводные!$F166, Q$3 <= Вводные!$G166), 1, 0) -> 1 | ... BJ37: =IF( AND(BJ$3 >= Вводные!$F166, BJ$3 <= Вводные!$G166), 1, 0) -> 0
D38: =Вводные!$D$119 -> Отпуск | E38: флаг | J38: =IF( AND(J$3 >= Вводные!$F167, J$3 <= Вводные!$G167), 1, 0) -> 1 | K38: =IF( AND(K$3 >= Вводные!$F167, K$3 <= Вводные!$G167), 1, 0) -> 1 | L38: =IF( AND(L$3 >= Вводные!$F167, L$3 <= Вводные!$G167), 1, 0) -> 1 | M38: =IF( AND(M$3 >= Вводные!$F167, M$3 <= Вводные!$G167), 1, 0) -> 1 | N38: =IF( AND(N$3 >= Вводные!$F167, N$3 <= Вводные!$G167), 1, 0) -> 1 | O38: =IF( AND(O$3 >= Вводные!$F167, O$3 <= Вводные!$G167), 1, 0) -> 1 | P38: =IF( AND(P$3 >= Вводные!$F167, P$3 <= Вводные!$G167), 1, 0) -> 1 | Q38: =IF( AND(Q$3 >= Вводные!$F167, Q$3 <= Вводные!$G167), 1, 0) -> 1 | ... BJ38: =IF( AND(BJ$3 >= Вводные!$F167, BJ$3 <= Вводные!$G167), 1, 0) -> 1
D39: =Вводные!$D$120 -> Долг 2 млн | E39: флаг | J39: =IF( AND(J$3 >= Вводные!$F168, J$3 <= Вводные!$G168), 1, 0) -> 1 | K39: =IF( AND(K$3 >= Вводные!$F168, K$3 <= Вводные!$G168), 1, 0) -> 1 | L39: =IF( AND(L$3 >= Вводные!$F168, L$3 <= Вводные!$G168), 1, 0) -> 0 | M39: =IF( AND(M$3 >= Вводные!$F168, M$3 <= Вводные!$G168), 1, 0) -> 0 | N39: =IF( AND(N$3 >= Вводные!$F168, N$3 <= Вводные!$G168), 1, 0) -> 0 | O39: =IF( AND(O$3 >= Вводные!$F168, O$3 <= Вводные!$G168), 1, 0) -> 0 | P39: =IF( AND(P$3 >= Вводные!$F168, P$3 <= Вводные!$G168), 1, 0) -> 0 | Q39: =IF( AND(Q$3 >= Вводные!$F168, Q$3 <= Вводные!$G168), 1, 0) -> 0 | ... BJ39: =IF( AND(BJ$3 >= Вводные!$F168, BJ$3 <= Вводные!$G168), 1, 0) -> 0
D40: =Вводные!$D$121 -> Долг за квартиру | E40: флаг | J40: =IF( AND(J$3 >= Вводные!$F169, J$3 <= Вводные!$G169), 1, 0) -> 1 | K40: =IF( AND(K$3 >= Вводные!$F169, K$3 <= Вводные!$G169), 1, 0) -> 1 | L40: =IF( AND(L$3 >= Вводные!$F169, L$3 <= Вводные!$G169), 1, 0) -> 1 | M40: =IF( AND(M$3 >= Вводные!$F169, M$3 <= Вводные!$G169), 1, 0) -> 1 | N40: =IF( AND(N$3 >= Вводные!$F169, N$3 <= Вводные!$G169), 1, 0) -> 1 | O40: =IF( AND(O$3 >= Вводные!$F169, O$3 <= Вводные!$G169), 1, 0) -> 0 | P40: =IF( AND(P$3 >= Вводные!$F169, P$3 <= Вводные!$G169), 1, 0) -> 0 | Q40: =IF( AND(Q$3 >= Вводные!$F169, Q$3 <= Вводные!$G169), 1, 0) -> 0 | ... BJ40: =IF( AND(BJ$3 >= Вводные!$F169, BJ$3 <= Вводные!$G169), 1, 0) -> 0
D41: =Вводные!$D$122 -> Подарки | E41: флаг | J41: =IF( AND(J$3 >= Вводные!$F170, J$3 <= Вводные!$G170), 1, 0) -> 1 | K41: =IF( AND(K$3 >= Вводные!$F170, K$3 <= Вводные!$G170), 1, 0) -> 1 | L41: =IF( AND(L$3 >= Вводные!$F170, L$3 <= Вводные!$G170), 1, 0) -> 1 | M41: =IF( AND(M$3 >= Вводные!$F170, M$3 <= Вводные!$G170), 1, 0) -> 1 | N41: =IF( AND(N$3 >= Вводные!$F170, N$3 <= Вводные!$G170), 1, 0) -> 1 | O41: =IF( AND(O$3 >= Вводные!$F170, O$3 <= Вводные!$G170), 1, 0) -> 1 | P41: =IF( AND(P$3 >= Вводные!$F170, P$3 <= Вводные!$G170), 1, 0) -> 1 | Q41: =IF( AND(Q$3 >= Вводные!$F170, Q$3 <= Вводные!$G170), 1, 0) -> 1 | ... BJ41: =IF( AND(BJ$3 >= Вводные!$F170, BJ$3 <= Вводные!$G170), 1, 0) -> 1
D42: =Вводные!$D$123 -> Ежегодный расход 8 | E42: флаг | J42: =IF( AND(J$3 >= Вводные!$F171, J$3 <= Вводные!$G171), 1, 0) -> 1 | K42: =IF( AND(K$3 >= Вводные!$F171, K$3 <= Вводные!$G171), 1, 0) -> 1 | L42: =IF( AND(L$3 >= Вводные!$F171, L$3 <= Вводные!$G171), 1, 0) -> 1 | M42: =IF( AND(M$3 >= Вводные!$F171, M$3 <= Вводные!$G171), 1, 0) -> 1 | N42: =IF( AND(N$3 >= Вводные!$F171, N$3 <= Вводные!$G171), 1, 0) -> 1 | O42: =IF( AND(O$3 >= Вводные!$F171, O$3 <= Вводные!$G171), 1, 0) -> 1 | P42: =IF( AND(P$3 >= Вводные!$F171, P$3 <= Вводные!$G171), 1, 0) -> 1 | Q42: =IF( AND(Q$3 >= Вводные!$F171, Q$3 <= Вводные!$G171), 1, 0) -> 1 | ... BJ42: =IF( AND(BJ$3 >= Вводные!$F171, BJ$3 <= Вводные!$G171), 1, 0) -> 1
D43: =Вводные!$D$124 -> Ежегодный расход 9 | E43: флаг | J43: =IF( AND(J$3 >= Вводные!$F172, J$3 <= Вводные!$G172), 1, 0) -> 1 | K43: =IF( AND(K$3 >= Вводные!$F172, K$3 <= Вводные!$G172), 1, 0) -> 1 | L43: =IF( AND(L$3 >= Вводные!$F172, L$3 <= Вводные!$G172), 1, 0) -> 1 | M43: =IF( AND(M$3 >= Вводные!$F172, M$3 <= Вводные!$G172), 1, 0) -> 1 | N43: =IF( AND(N$3 >= Вводные!$F172, N$3 <= Вводные!$G172), 1, 0) -> 1 | O43: =IF( AND(O$3 >= Вводные!$F172, O$3 <= Вводные!$G172), 1, 0) -> 1 | P43: =IF( AND(P$3 >= Вводные!$F172, P$3 <= Вводные!$G172), 1, 0) -> 1 | Q43: =IF( AND(Q$3 >= Вводные!$F172, Q$3 <= Вводные!$G172), 1, 0) -> 1 | ... BJ43: =IF( AND(BJ$3 >= Вводные!$F172, BJ$3 <= Вводные!$G172), 1, 0) -> 1
D44: =Вводные!$D$125 -> Ежегодный расход 10 | E44: флаг | J44: =IF( AND(J$3 >= Вводные!$F173, J$3 <= Вводные!$G173), 1, 0) -> 1 | K44: =IF( AND(K$3 >= Вводные!$F173, K$3 <= Вводные!$G173), 1, 0) -> 1 | L44: =IF( AND(L$3 >= Вводные!$F173, L$3 <= Вводные!$G173), 1, 0) -> 1 | M44: =IF( AND(M$3 >= Вводные!$F173, M$3 <= Вводные!$G173), 1, 0) -> 1 | N44: =IF( AND(N$3 >= Вводные!$F173, N$3 <= Вводные!$G173), 1, 0) -> 1 | O44: =IF( AND(O$3 >= Вводные!$F173, O$3 <= Вводные!$G173), 1, 0) -> 1 | P44: =IF( AND(P$3 >= Вводные!$F173, P$3 <= Вводные!$G173), 1, 0) -> 1 | Q44: =IF( AND(Q$3 >= Вводные!$F173, Q$3 <= Вводные!$G173), 1, 0) -> 1 | ... BJ44: =IF( AND(BJ$3 >= Вводные!$F173, BJ$3 <= Вводные!$G173), 1, 0) -> 1
B46: =MAX( $B$7:B43 ) + 1 -> 2 | D46: Расходы
D48: Всего расходы | E48: USD / год | I48: =SUM(I52,I98) -> -117000 | J48: =SUM(J52,J98) -> -117000 | K48: =SUM(K52,K98) -> -119880 | L48: =SUM(L52,L98) -> -119846.4 | M48: =SUM(M52,M98) -> -122901.79 | N48: =SUM(N52,N98) -> -126048.85 | O48: =SUM(O52,O98) -> -126290.31 | P48: =SUM(P52,P98) -> -129629.02 | ... BJ48: =SUM(BJ52,BJ98) -> -432532.39
C50: =MAX( $B$7:C47 ) + 0.1 -> 2.1 | D50: Ежемесячные расходы
...

Sheet Цели
D3: =Вводные!D3 -> Год | J3: =Вводные!J3 -> 2024 | K3: =Вводные!K3 -> 2025 | L3: =Вводные!L3 -> 2026 | M3: =Вводные!M3 -> 2027 | N3: =Вводные!N3 -> 2028 | O3: =Вводные!O3 -> 2029 | P3: =Вводные!P3 -> 2030 | Q3: =Вводные!Q3 -> 2031 | ... BJ3: =Вводные!BJ3 -> 2076
D4: =Вводные!D4 -> Возраст | J4: =Вводные!J4 -> 31 | K4: =Вводные!K4 -> 32 | L4: =Вводные!L4 -> 33 | M4: =Вводные!M4 -> 34 | N4: =Вводные!N4 -> 35 | O4: =Вводные!O4 -> 36 | P4: =Вводные!P4 -> 37 | Q4: =Вводные!Q4 -> 38 | ... BJ4: =Вводные!BJ4 -> 83
D5: =Вводные!D5 -> № периода | J5: =Вводные!J5 -> 1 | K5: =Вводные!K5 -> 2 | L5: =Вводные!L5 -> 3 | M5: =Вводные!M5 -> 4 | N5: =Вводные!N5 -> 5 | O5: =Вводные!O5 -> 6 | P5: =Вводные!P5 -> 7 | Q5: =Вводные!Q5 -> 8 | ... BJ5: =Вводные!BJ5 -> 53
B8: =MAX( $B5:B$7 ) + 1 -> 1 | D8: Флаги
C10: =MAX( $B$7:C9 ) + 0.1 -> 1.1 | D10: Флаги понесения расходов
D12: Ежемесячные расходы на цели
D13: =Вводные!$D$180 -> Ежемесячный расход на цели 1 | E13: флаг | J13: =IF( AND(J$3 >= Вводные!$F232, J$3 <= Вводные!$G232), 1, 0) -> 1 | K13: =IF( AND(K$3 >= Вводные!$F232, K$3 <= Вводные!$G232), 1, 0) -> 1 | L13: =IF( AND(L$3 >= Вводные!$F232, L$3 <= Вводные!$G232), 1, 0) -> 1 | M13: =IF( AND(M$3 >= Вводные!$F232, M$3 <= Вводные!$G232), 1, 0) -> 1 | N13: =IF( AND(N$3 >= Вводные!$F232, N$3 <= Вводные!$G232), 1, 0) -> 1 | O13: =IF( AND(O$3 >= Вводные!$F232, O$3 <= Вводные!$G232), 1, 0) -> 1 | P13: =IF( AND(P$3 >= Вводные!$F232, P$3 <= Вводные!$G232), 1, 0) -> 1 | Q13: =IF( AND(Q$3 >= Вводные!$F232, Q$3 <= Вводные!$G232), 1, 0) -> 1 | ... BJ13: =IF( AND(BJ$3 >= Вводные!$F232, BJ$3 <= Вводные!$G232), 1, 0) -> 0
D14: =Вводные!$D$181 -> Ежемесячный расход на цели 2 | E14: флаг | J14: =IF( AND(J$3 >= Вводные!$F233, J$3 <= Вводные!$G233), 1, 0) -> 1 | K14: =IF( AND(K$3 >= Вводные!$F233, K$3 <= Вводные!$G233), 1, 0) -> 1 | L14: =IF( AND(L$3 >= Вводные!$F233, L$3 <= Вводные!$G233), 1, 0) -> 1 | M14: =IF( AND(M$3 >= Вводные!$F233, M$3 <= Вводные!$G233), 1, 0) -> 1 | N14: =IF( AND(N$3 >= Вводные!$F233, N$3 <= Вводные!$G233), 1, 0) -> 1 | O14: =IF( AND(O$3 >= Вводные!$F233, O$3 <= Вводные!$G233), 1, 0) -> 1 | P14: =IF( AND(P$3 >= Вводные!$F233, P$3 <= Вводные!$G233), 1, 0) -> 1 | Q14: =IF( AND(Q$3 >= Вводные!$F233, Q$3 <= Вводные!$G233), 1, 0) -> 1 | ... BJ14: =IF( AND(BJ$3 >= Вводные!$F233, BJ$3 <= Вводные!$G233), 1, 0) -> 0
D15: =Вводные!$D$182 -> Ежемесячный расход на цели 3 | E15: флаг | J15: =IF( AND(J$3 >= Вводные!$F234, J$3 <= Вводные!$G234), 1, 0) -> 1 | K15: =IF( AND(K$3 >= Вводные!$F234, K$3 <= Вводные!$G234), 1, 0) -> 1 | L15: =IF( AND(L$3 >= Вводные!$F234, L$3 <= Вводные!$G234), 1, 0) -> 1 | M15: =IF( AND(M$3 >= Вводные!$F234, M$3 <= Вводные!$G234), 1, 0) -> 1 | N15: =IF( AND(N$3 >= Вводные!$F234, N$3 <= Вводные!$G234), 1, 0) -> 1 | O15: =IF( AND(O$3 >= Вводные!$F234, O$3 <= Вводные!$G234), 1, 0) -> 1 | P15: =IF( AND(P$3 >= Вводные!$F234, P$3 <= Вводные!$G234), 1, 0) -> 1 | Q15: =IF( AND(Q$3 >= Вводные!$F234, Q$3 <= Вводные!$G234), 1, 0) -> 1 | ... BJ15: =IF( AND(BJ$3 >= Вводные!$F234, BJ$3 <= Вводные!$G234), 1, 0) -> 0
D16: =Вводные!$D$183 -> Ежемесячный расход на цели 4 | E16: флаг | J16: =IF( AND(J$3 >= Вводные!$F235, J$3 <= Вводные!$G235), 1, 0) -> 1 | K16: =IF( AND(K$3 >= Вводные!$F235, K$3 <= Вводные!$G235), 1, 0) -> 1 | L16: =IF( AND(L$3 >= Вводные!$F235, L$3 <= Вводные!$G235), 1, 0) -> 1 | M16: =IF( AND(M$3 >= Вводные!$F235, M$3 <= Вводные!$G235), 1, 0) -> 1 | N16: =IF( AND(N$3 >= Вводные!$F235, N$3 <= Вводные!$G235), 1, 0) -> 1 | O16: =IF( AND(O$3 >= Вводные!$F235, O$3 <= Вводные!$G235), 1, 0) -> 1 | P16: =IF( AND(P$3 >= Вводные!$F235, P$3 <= Вводные!$G235), 1, 0) -> 1 | Q16: =IF( AND(Q$3 >= Вводные!$F235, Q$3 <= Вводные!$G235), 1, 0) -> 1 | ... BJ16: =IF( AND(BJ$3 >= Вводные!$F235, BJ$3 <= Вводные!$G235), 1, 0) -> 0
D17: =Вводные!$D$184 -> Ежемесячный расход на цели 5 | E17: флаг | J17: =IF( AND(J$3 >= Вводные!$F236, J$3 <= Вводные!$G236), 1, 0) -> 1 | K17: =IF( AND(K$3 >= Вводные!$F236, K$3 <= Вводные!$G236), 1, 0) -> 1 | L17: =IF( AND(L$3 >= Вводные!$F236, L$3 <= Вводные!$G236), 1, 0) -> 1 | M17: =IF( AND(M$3 >= Вводные!$F236, M$3 <= Вводные!$G236), 1, 0) -> 1 | N17: =IF( AND(N$3 >= Вводные!$F236, N$3 <= Вводные!$G236), 1, 0) -> 1 | O17: =IF( AND(O$3 >= Вводные!$F236, O$3 <= Вводные!$G236), 1, 0) -> 1 | P17: =IF( AND(P$3 >= Вводные!$F236, P$3 <= Вводные!$G236), 1, 0) -> 1 | Q17: =IF( AND(Q$3 >= Вводные!$F236, Q$3 <= Вводные!$G236), 1, 0) -> 1 | ... BJ17: =IF( AND(BJ$3 >= Вводные!$F236, BJ$3 <= Вводные!$G236), 1, 0) -> 0
D18: =Вводные!$D$185 -> Ежемесячный расход на цели 6 | E18: флаг | J18: =IF( AND(J$3 >= Вводные!$F237, J$3 <= Вводные!$G237), 1, 0) -> 1 | K18: =IF( AND(K$3 >= Вводные!$F237, K$3 <= Вводные!$G237), 1, 0) -> 1 | L18: =IF( AND(L$3 >= Вводные!$F237, L$3 <= Вводные!$G237), 1, 0) -> 1 | M18: =IF( AND(M$3 >= Вводные!$F237, M$3 <= Вводные!$G237), 1, 0) -> 1 | N18: =IF( AND(N$3 >= Вводные!$F237, N$3 <= Вводные!$G237), 1, 0) -> 1 | O18: =IF( AND(O$3 >= Вводные!$F237, O$3 <= Вводные!$G237), 1, 0) -> 1 | P18: =IF( AND(P$3 >= Вводные!$F237, P$3 <= Вводные!$G237), 1, 0) -> 1 | Q18: =IF( AND(Q$3 >= Вводные!$F237, Q$3 <= Вводные!$G237), 1, 0) -> 1 | ... BJ18: =IF( AND(BJ$3 >= Вводные!$F237, BJ$3 <= Вводные!$G237), 1, 0) -> 0
D19: =Вводные!$D$186 -> Ежемесячный расход на цели 7 | E19: флаг | J19: =IF( AND(J$3 >= Вводные!$F238, J$3 <= Вводные!$G238), 1, 0) -> 1 | K19: =IF( AND(K$3 >= Вводные!$F238, K$3 <= Вводные!$G238), 1, 0) -> 1 | L19: =IF( AND(L$3 >= Вводные!$F238, L$3 <= Вводные!$G238), 1, 0) -> 1 | M19: =IF( AND(M$3 >= Вводные!$F238, M$3 <= Вводные!$G238), 1, 0) -> 1 | N19: =IF( AND(N$3 >= Вводные!$F238, N$3 <= Вводные!$G238), 1, 0) -> 1 | O19: =IF( AND(O$3 >= Вводные!$F238, O$3 <= Вводные!$G238), 1, 0) -> 1 | P19: =IF( AND(P$3 >= Вводные!$F238, P$3 <= Вводные!$G238), 1, 0) -> 1 | Q19: =IF( AND(Q$3 >= Вводные!$F238, Q$3 <= Вводные!$G238), 1, 0) -> 1 | ... BJ19: =IF( AND(BJ$3 >= Вводные!$F238, BJ$3 <= Вводные!$G238), 1, 0) -> 0
D20: =Вводные!$D$187 -> Ежемесячный расход на цели 8 | E20: флаг | J20: =IF( AND(J$3 >= Вводные!$F239, J$3 <= Вводные!$G239), 1, 0) -> 1 | K20: =IF( AND(K$3 >= Вводные!$F239, K$3 <= Вводные!$G239), 1, 0) -> 1 | L20: =IF( AND(L$3 >= Вводные!$F239, L$3 <= Вводные!$G239), 1, 0) -> 1 | M20: =IF( AND(M$3 >= Вводные!$F239, M$3 <= Вводные!$G239), 1, 0) -> 1 | N20: =IF( AND(N$3 >= Вводные!$F239, N$3 <= Вводные!$G239), 1, 0) -> 1 | O20: =IF( AND(O$3 >= Вводные!$F239, O$3 <= Вводные!$G239), 1, 0) -> 1 | P20: =IF( AND(P$3 >= Вводные!$F239, P$3 <= Вводные!$G239), 1, 0) -> 1 | Q20: =IF( AND(Q$3 >= Вводные!$F239, Q$3 <= Вводные!$G239), 1, 0) -> 1 | ... BJ20: =IF( AND(BJ$3 >= Вводные!$F239, BJ$3 <= Вводные!$G239), 1, 0) -> 0
D21: =Вводные!$D$188 -> Ежемесячный расход на цели 9 | E21: флаг | J21: =IF( AND(J$3 >= Вводные!$F240, J$3 <= Вводные!$G240), 1, 0) -> 1 | K21: =IF( AND(K$3 >= Вводные!$F240, K$3 <= Вводные!$G240), 1, 0) -> 1 | L21: =IF( AND(L$3 >= Вводные!$F240, L$3 <= Вводные!$G240), 1, 0) -> 1 | M21: =IF( AND(M$3 >= Вводные!$F240, M$3 <= Вводные!$G240), 1, 0) -> 1 | N21: =IF( AND(N$3 >= Вводные!$F240, N$3 <= Вводные!$G240), 1, 0) -> 1 | O21: =IF( AND(O$3 >= Вводные!$F240, O$3 <= Вводные!$G240), 1, 0) -> 1 | P21: =IF( AND(P$3 >= Вводные!$F240, P$3 <= Вводные!$G240), 1, 0) -> 1 | Q21: =IF( AND(Q$3 >= Вводные!$F240, Q$3 <= Вводные!$G240), 1, 0) -> 1 | ... BJ21: =IF( AND(BJ$3 >= Вводные!$F240, BJ$3 <= Вводные!$G240), 1, 0) -> 0
D22: =Вводные!$D$189 -> Ежемесячный расход на цели 10 | E22: флаг | J22: =IF( AND(J$3 >= Вводные!$F241, J$3 <= Вводные!$G241), 1, 0) -> 1 | K22: =IF( AND(K$3 >= Вводные!$F241, K$3 <= Вводные!$G241), 1, 0) -> 1 | L22: =IF( AND(L$3 >= Вводные!$F241, L$3 <= Вводные!$G241), 1, 0) -> 1 | M22: =IF( AND(M$3 >= Вводные!$F241, M$3 <= Вводные!$G241), 1, 0) -> 1 | N22: =IF( AND(N$3 >= Вводные!$F241, N$3 <= Вводные!$G241), 1, 0) -> 1 | O22: =IF( AND(O$3 >= Вводные!$F241, O$3 <= Вводные!$G241), 1, 0) -> 1 | P22: =IF( AND(P$3 >= Вводные!$F241, P$3 <= Вводные!$G241), 1, 0) -> 1 | Q22: =IF( AND(Q$3 >= Вводные!$F241, Q$3 <= Вводные!$G241), 1, 0) -> 1 | ... BJ22: =IF( AND(BJ$3 >= Вводные!$F241, BJ$3 <= Вводные!$G241), 1, 0) -> 0
D24: Ежегодные расходы на цели
D25: =Вводные!$D$180 -> Ежемесячный расход на цели 1 | E25: флаг | J25: =IF( AND(J$3 >= Вводные!$F244, J$3 <= Вводные!$G244), 1, 0) -> 1 | K25: =IF( AND(K$3 >= Вводные!$F244, K$3 <= Вводные!$G244), 1, 0) -> 1 | L25: =IF( AND(L$3 >= Вводные!$F244, L$3 <= Вводные!$G244), 1, 0) -> 1 | M25: =IF( AND(M$3 >= Вводные!$F244, M$3 <= Вводные!$G244), 1, 0) -> 1 | N25: =IF( AND(N$3 >= Вводные!$F244, N$3 <= Вводные!$G244), 1, 0) -> 1 | O25: =IF( AND(O$3 >= Вводные!$F244, O$3 <= Вводные!$G244), 1, 0) -> 1 | P25: =IF( AND(P$3 >= Вводные!$F244, P$3 <= Вводные!$G244), 1, 0) -> 1 | Q25: =IF( AND(Q$3 >= Вводные!$F244, Q$3 <= Вводные!$G244), 1, 0) -> 1 | ... BJ25: =IF( AND(BJ$3 >= Вводные!$F244, BJ$3 <= Вводные!$G244), 1, 0) -> 0
D26: =Вводные!$D$181 -> Ежемесячный расход на цели 2 | E26: флаг | J26: =IF( AND(J$3 >= Вводные!$F245, J$3 <= Вводные!$G245), 1, 0) -> 1 | K26: =IF( AND(K$3 >= Вводные!$F245, K$3 <= Вводные!$G245), 1, 0) -> 1 | L26: =IF( AND(L$3 >= Вводные!$F245, L$3 <= Вводные!$G245), 1, 0) -> 1 | M26: =IF( AND(M$3 >= Вводные!$F245, M$3 <= Вводные!$G245), 1, 0) -> 1 | N26: =IF( AND(N$3 >= Вводные!$F245, N$3 <= Вводные!$G245), 1, 0) -> 1 | O26: =IF( AND(O$3 >= Вводные!$F245, O$3 <= Вводные!$G245), 1, 0) -> 1 | P26: =IF( AND(P$3 >= Вводные!$F245, P$3 <= Вводные!$G245), 1, 0) -> 1 | Q26: =IF( AND(Q$3 >= Вводные!$F245, Q$3 <= Вводные!$G245), 1, 0) -> 1 | ... BJ26: =IF( AND(BJ$3 >= Вводные!$F245, BJ$3 <= Вводные!$G245), 1, 0) -> 0
D27: =Вводные!$D$182 -> Ежемесячный расход на цели 3 | E27: флаг | J27: =IF( AND(J$3 >= Вводные!$F246, J$3 <= Вводные!$G246), 1, 0) -> 1 | K27: =IF( AND(K$3 >= Вводные!$F246, K$3 <= Вводные!$G246), 1, 0) -> 1 | L27: =IF( AND(L$3 >= Вводные!$F246, L$3 <= Вводные!$G246), 1, 0) -> 1 | M27: =IF( AND(M$3 >= Вводные!$F246, M$3 <= Вводные!$G246), 1, 0) -> 1 | N27: =IF( AND(N$3 >= Вводные!$F246, N$3 <= Вводные!$G246), 1, 0) -> 1 | O27: =IF( AND(O$3 >= Вводные!$F246, O$3 <= Вводные!$G246), 1, 0) -> 1 | P27: =IF( AND(P$3 >= Вводные!$F246, P$3 <= Вводные!$G246), 1, 0) -> 1 | Q27: =IF( AND(Q$3 >= Вводные!$F246, Q$3 <= Вводные!$G246), 1, 0) -> 1 | ... BJ27: =IF( AND(BJ$3 >= Вводные!$F246, BJ$3 <= Вводные!$G246), 1, 0) -> 0
D28: =Вводные!$D$183 -> Ежемесячный расход на цели 4 | E28: флаг | J28: =IF( AND(J$3 >= Вводные!$F247, J$3 <= Вводные!$G247), 1, 0) -> 1 | K28: =IF( AND(K$3 >= Вводные!$F247, K$3 <= Вводные!$G247), 1, 0) -> 1 | L28: =IF( AND(L$3 >= Вводные!$F247, L$3 <= Вводные!$G247), 1, 0) -> 1 | M28: =IF( AND(M$3 >= Вводные!$F247, M$3 <= Вводные!$G247), 1, 0) -> 1 | N28: =IF( AND(N$3 >= Вводные!$F247, N$3 <= Вводные!$G247), 1, 0) -> 1 | O28: =IF( AND(O$3 >= Вводные!$F247, O$3 <= Вводные!$G247), 1, 0) -> 1 | P28: =IF( AND(P$3 >= Вводные!$F247, P$3 <= Вводные!$G247), 1, 0) -> 1 | Q28: =IF( AND(Q$3 >= Вводные!$F247, Q$3 <= Вводные!$G247), 1, 0) -> 1 | ... BJ28: =IF( AND(BJ$3 >= Вводные!$F247, BJ$3 <= Вводные!$G247), 1, 0) -> 0
D29: =Вводные!$D$184 -> Ежемесячный расход на цели 5 | E29: флаг | J29: =IF( AND(J$3 >= Вводные!$F248, J$3 <= Вводные!$G248), 1, 0) -> 1 | K29: =IF( AND(K$3 >= Вводные!$F248, K$3 <= Вводные!$G248), 1, 0) -> 1 | L29: =IF( AND(L$3 >= Вводные!$F248, L$3 <= Вводные!$G248), 1, 0) -> 1 | M29: =IF( AND(M$3 >= Вводные!$F248, M$3 <= Вводные!$G248), 1, 0) -> 1 | N29: =IF( AND(N$3 >= Вводные!$F248, N$3 <= Вводные!$G248), 1, 0) -> 1 | O29: =IF( AND(O$3 >= Вводные!$F248, O$3 <= Вводные!$G248), 1, 0) -> 1 | P29: =IF( AND(P$3 >= Вводные!$F248, P$3 <= Вводные!$G248), 1, 0) -> 1 | Q29: =IF( AND(Q$3 >= Вводные!$F248, Q$3 <= Вводные!$G248), 1, 0) -> 1 | ... BJ29: =IF( AND(BJ$3 >= Вводные!$F248, BJ$3 <= Вводные!$G248), 1, 0) -> 0
D30: =Вводные!$D$185 -> Ежемесячный расход на цели 6 | E30: флаг | J30: =IF( AND(J$3 >= Вводные!$F249, J$3 <= Вводные!$G249), 1, 0) -> 1 | K30: =IF( AND(K$3 >= Вводные!$F249, K$3 <= Вводные!$G249), 1, 0) -> 1 | L30: =IF( AND(L$3 >= Вводные!$F249, L$3 <= Вводные!$G249), 1, 0) -> 1 | M30: =IF( AND(M$3 >= Вводные!$F249, M$3 <= Вводные!$G249), 1, 0) -> 1 | N30: =IF( AND(N$3 >= Вводные!$F249, N$3 <= Вводные!$G249), 1, 0) -> 1 | O30: =IF( AND(O$3 >= Вводные!$F249, O$3 <= Вводные!$G249), 1, 0) -> 1 | P30: =IF( AND(P$3 >= Вводные!$F249, P$3 <= Вводные!$G249), 1, 0) -> 1 | Q30: =IF( AND(Q$3 >= Вводные!$F249, Q$3 <= Вводные!$G249), 1, 0) -> 1 | ... BJ30: =IF( AND(BJ$3 >= Вводные!$F249, BJ$3 <= Вводные!$G249), 1, 0) -> 0
D31: =Вводные!$D$186 -> Ежемесячный расход на цели 7 | E31: флаг | J31: =IF( AND(J$3 >= Вводные!$F250, J$3 <= Вводные!$G250), 1, 0) -> 1 | K31: =IF( AND(K$3 >= Вводные!$F250, K$3 <= Вводные!$G250), 1, 0) -> 1 | L31: =IF( AND(L$3 >= Вводные!$F250, L$3 <= Вводные!$G250), 1, 0) -> 1 | M31: =IF( AND(M$3 >= Вводные!$F250, M$3 <= Вводные!$G250), 1, 0) -> 1 | N31: =IF( AND(N$3 >= Вводные!$F250, N$3 <= Вводные!$G250), 1, 0) -> 1 | O31: =IF( AND(O$3 >= Вводные!$F250, O$3 <= Вводные!$G250), 1, 0) -> 1 | P31: =IF( AND(P$3 >= Вводные!$F250, P$3 <= Вводные!$G250), 1, 0) -> 1 | Q31: =IF( AND(Q$3 >= Вводные!$F250, Q$3 <= Вводные!$G250), 1, 0) -> 1 | ... BJ31: =IF( AND(BJ$3 >= Вводные!$F250, BJ$3 <= Вводные!$G250), 1, 0) -> 0
D32: =Вводные!$D$187 -> Ежемесячный расход на цели 8 | E32: флаг | J32: =IF( AND(J$3 >= Вводные!$F251, J$3 <= Вводные!$G251), 1, 0) -> 1 | K32: =IF( AND(K$3 >= Вводные!$F251, K$3 <= Вводные!$G251), 1, 0) -> 1 | L32: =IF( AND(L$3 >= Вводные!$F251, L$3 <= Вводные!$G251), 1, 0) -> 1 | M32: =IF( AND(M$3 >= Вводные!$F251, M$3 <= Вводные!$G251), 1, 0) -> 1 | N32: =IF( AND(N$3 >= Вводные!$F251, N$3 <= Вводные!$G251), 1, 0) -> 1 | O32: =IF( AND(O$3 >= Вводные!$F251, O$3 <= Вводные!$G251), 1, 0) -> 1 | P32: =IF( AND(P$3 >= Вводные!$F251, P$3 <= Вводные!$G251), 1, 0) -> 1 | Q32: =IF( AND(Q$3 >= Вводные!$F251, Q$3 <= Вводные!$G251), 1, 0) -> 1 | ... BJ32: =IF( AND(BJ$3 >= Вводные!$F251, BJ$3 <= Вводные!$G251), 1, 0) -> 0
D33: =Вводные!$D$188 -> Ежемесячный расход на цели 9 | E33: флаг | J33: =IF( AND(J$3 >= Вводные!$F252, J$3 <= Вводные!$G252), 1, 0) -> 1 | K33: =IF( AND(K$3 >= Вводные!$F252, K$3 <= Вводные!$G252), 1, 0) -> 1 | L33: =IF( AND(L$3 >= Вводные!$F252, L$3 <= Вводные!$G252), 1, 0) -> 1 | M33: =IF( AND(M$3 >= Вводные!$F252, M$3 <= Вводные!$G252), 1, 0) -> 1 | N33: =IF( AND(N$3 >= Вводные!$F252, N$3 <= Вводные!$G252), 1, 0) -> 1 | O33: =IF( AND(O$3 >= Вводные!$F252, O$3 <= Вводные!$G252), 1, 0) -> 1 | P33: =IF( AND(P$3 >= Вводные!$F252, P$3 <= Вводные!$G252), 1, 0) -> 1 | Q33: =IF( AND(Q$3 >= Вводные!$F252, Q$3 <= Вводные!$G252), 1, 0) -> 1 | ... BJ33: =IF( AND(BJ$3 >= Вводные!$F252, BJ$3 <= Вводные!$G252), 1, 0) -> 0
D34: =Вводные!$D$189 -> Ежемесячный расход на цели 10 | E34: флаг | J34: =IF( AND(J$3 >= Вводные!$F253, J$3 <= Вводные!$G253), 1, 0) -> 1 | K34: =IF( AND(K$3 >= Вводные!$F253, K$3 <= Вводные!$G253), 1, 0) -> 1 | L34: =IF( AND(L$3 >= Вводные!$F253, L$3 <= Вводные!$G253), 1, 0) -> 1 | M34: =IF( AND(M$3 >= Вводные!$F253, M$3 <= Вводные!$G253), 1, 0) -> 1 | N34: =IF( AND(N$3 >= Вводные!$F253, N$3 <= Вводные!$G253), 1, 0) -> 1 | O34: =IF( AND(O$3 >= Вводные!$F253, O$3 <= Вводные!$G253), 1, 0) -> 1 | P34: =IF( AND(P$3 >= Вводные!$F253, P$3 <= Вводные!$G253), 1, 0) -> 1 | Q34: =IF( AND(Q$3 >= Вводные!$F253, Q$3 <= Вводные!$G253), 1, 0) -> 1 | ... BJ34: =IF( AND(BJ$3 >= Вводные!$F253, BJ$3 <= Вводные!$G253), 1, 0) -> 0
B36: =MAX( $B$7:B33 ) + 1 -> 2 | D36: Расходы на цели
D38: Всего расходы на цели | E38: USD / год | I38: =SUM(I42,I68) -> -20000 | J38: =SUM(J42,J68) -> -20000 | K38: =SUM(K42,K68) -> -20600 | L38: =SUM(L42,L68) -> -21218 | M38: =SUM(M42,M68) -> -21854.54 | N38: =SUM(N42,N68) -> -22510.176 | O38: =SUM(O42,O68) -> -23185.481 | P38: =SUM(P42,P68) -> -23881.046 | ... BJ38: =SUM(BJ42,BJ68) -> 0
C40: =MAX( $B$36:C37 ) + 0.1 -> 2.1 | D40: Ежемесячные расходы на цели
D42: Ежемесячные расходы на цели | E42: USD / год | I42: =SUM(I43:I52) -> 0 | J42: =SUM(J43:J52) -> 0 | K42: =SUM(K43:K52) -> 0 | L42: =SUM(L43:L52) -> 0 | M42: =SUM(M43:M52) -> 0 | N42: =SUM(N43:N52) -> 0 | O42: =SUM(O43:O52) -> 0 | P42: =SUM(P43:P52) -> 0 | ... BJ42: =SUM(BJ43:BJ52) -> 0
D43: =Вводные!$D$180 -> Ежемесячный расход на цели 1 | E43: USD / год | I43: =Вводные!F180 * Вводные!$F$12 -> 0 | J43: =$I43 * J55 * J13 -> 0 | K43: =$I43 * K55 * K13 -> 0 | L43: =$I43 * L55 * L13 -> 0 | M43: =$I43 * M55 * M13 -> 0 | N43: =$I43 * N55 * N13 -> 0 | O43: =$I43 * O55 * O13 -> 0 | P43: =$I43 * P55 * P13 -> 0 | Q43: =$I43 * Q55 * Q13 -> 0 | ... BJ43: =$I43 * BJ55 * BJ13 -> 0
D44: =Вводные!$D$181 -> Ежемесячный расход на цели 2 | E44: USD / год | I44: =Вводные!F181 * Вводные!$F$12 -> 0 | J44: =$I44 * J56 * J14 -> 0 | K44: =$I44 * K56 * K14 -> 0 | L44: =$I44 * L56 * L14 -> 0 | M44: =$I44 * M56 * M14 -> 0 | N44: =$I44 * N56 * N14 -> 0 | O44: =$I44 * O56 * O14 -> 0 | P44: =$I44 * P56 * P14 -> 0 | Q44: =$I44 * Q56 * Q14 -> 0 | ... BJ44: =$I44 * BJ56 * BJ14 -> 0
D45: =Вводные!$D$182 -> Ежемесячный расход на цели 3 | E45: USD / год | I45: =Вводные!F182 * Вводные!$F$12 -> 0 | J45: =$I45 * J57 * J15 -> 0 | K45: =$I45 * K57 * K15 -> 0 | L45: =$I45 * L57 * L15 -> 0 | M45: =$I45 * M57 * M15 -> 0 | N45: =$I45 * N57 * N15 -> 0 | O45: =$I45 * O57 * O15 -> 0 | P45: =$I45 * P57 * P15 -> 0 | Q45: =$I45 * Q57 * Q15 -> 0 | ... BJ45: =$I45 * BJ57 * BJ15 -> 0
